Workbook

Sheet POSTAVKE
A1: POSTAVKE MODELA
A3: Datum izvještaja | B3: 46268
A4: Datum prethodnog izvoza | B4: 46265
A5: Tranzit iz Kine (mjeseci) | B5: 4
A6: Sigurnosni prag (mjeseci) | B6: 5
A7: Broj završenih mjeseci prodaje | B7: 8
A9: Žuta polja se ručno mijenjaju. Sve ostalo se računa automatski.
A10: Prosjek se računa samo iz ZAVRŠENIH mjeseci (POSTAVKE B7).

Sheet PODACI_ZALIHE
A1: Artikal | B1: Naziv artikla | C1: Sifra dob. | D1: Naziv dobavljaca | E1: Zaliha prethodno | F1: Zaliha | G1: Izvor
A2: 16958 | B2: KERAMIČKI OVLAŽIVAČ ZRAKA ZA RADIJATOR 20x8.5x3.5 cm | E2: 1595 | F2: 1595
A3: 00617 | B3: MIJEŠALICA ZA SUDOPER PROTOČNI BOJLER | C3: 2974 | D3: TAIZHOU MINUOTE SANITARY WARES CO.,LTD. | E3: 932 | F3: 932
A4: 00836 | B4: GL11428 SIFON ZA TUŠ KADU LUX 60 mm | C4: 3291 | D4: TEHNOEXPORT D.O.O. | E4: 664 | F4: 561
A5: 16856 | B5: MOHO WC MONOBLOK PODNI ODVOD 665x375x725 mm | E5: 526 | F5: 526
A6: 18749 | B6: ZIDNI PANEL PVC NATURAL HRAST 3000x200x5 mm | C6: 6931 | D6: INTCO INTERNATIONAL (HK) CO., LIMITED | E6: 504 | F6: 503
A7: 00875 | B7: SET KOTAČIĆA ZA TUŠ KABINE 4/1 SW | C7: 4328 | D7: HANGZHOU DUHUI IMPORT AND EXPORT CO.,LTD | E7: 540 | F7: 500
A8: 044450 | B8: SIFON ZA UMIVAONIK 5/4 CRNI MESING | C8: 4826 | D8: TAIZHOU NIXI SANITARY WARE CO.,LTD | E8: 500 | F8: 500
A9: 00893 | B9: GLA011 PILETA ZA UMIVAONIK 5/4 | C9: 2974 | D9: TAIZHOU MINUOTE SANITARY WARES CO.,LTD. | E9: 489 | F9: 479
A10: 088939 | B10: PILETA UNIVERZALNA KROM 5/4 | E10: 453 | F10: 453
A11: 046203 | B11: ZELENA OBLOGA ZA ZID NATURA BOSCO | C11: 6931 | D11: INTCO INTERNATIONAL (HK) CO., LIMITED | E11: 405 | F11: 405
A12: 046205 | B12: ZELENA OBLOGA ZA ZID NATURA TERRANA | C12: 6931 | D12: INTCO INTERNATIONAL (HK) CO., LIMITED | E12: 405 | F12: 405
A13: 17173 | B13: NERO KUPAONSKA KUKICA ZA RUČNIK - CRNA | C13: 6458 | D13: BOJIA TRADING LIMITED | E13: 401 | F13: 401
A14: RDE320230 | B14: DASKA SOFT CLOSE ZA MOHO MONOBLOCK | C14: 6341 | D14: CORRAVENI INDUSTRIES CO., LTD. | E14: 380 | F14: 380
A15: 00720 | B15: KOTAČIĆI ZA TUŠ KABINE 4/1 | C15: 4328 | D15: HANGZHOU DUHUI IMPORT AND EXPORT CO.,LTD | E15: 385 | F15: 354
A16: 046204 | B16: ZELENA OBLOGA ZA ZID NATURA HERBA | C16: 6931 | D16: INTCO INTERNATIONAL (HK) CO., LIMITED | E16: 345 | F16: 345
A17: 046202 | B17: ZELENA OBLOGA ZA ZID VERDE FOREST | C17: 6931 | D17: INTCO INTERNATIONAL (HK) CO., LIMITED | E17: 335 | F17: 335
A18: 15399 | B18: PULSE 80 POLUKRUŽNA TUŠ KABINA 80X80X198 | C18: 6163 | D18: HANGZHOU TIANMEI INDUSTRY CO.,LTD | E18: 333 | F18: 321
A19: 17174 | B19: NERO DRŽAČ TOALETNOG PAPIRA - CRNI | C19: 6458 | D19: BOJIA TRADING LIMITED | E19: 311 | F19: 311
A20: 16935 | B20: ZOYA BLACK OGLEDALO R 80 cm | C20: 6032 | D20: HANGZHOU ZIHAN MIRROR INDUSTRY CO., LTD. | E20: 287 | F20: 282
A21: 16793 | B21: GL00099 FLEKSIBILNI SIFON TUS KADE LUX 110 SLIM | C21: 3291 | D21: TEHNOEXPORT D.O.O. | E21: 281 | F21: 281
A22: 15451 | B22: PULSE 90 POLUKRUŽNA TUŠ KABINA 90X90X198 | C22: 6163 | D22: HANGZHOU TIANMEI INDUSTRY CO.,LTD | E22: 304 | F22: 280
... A42: 00835 | B42: GL11427 SIFON ZA TUŠ KADU CLICK MESING | C42: 3291 | D42: TEHNOEXPORT D.O.O. | E42: 237 | F42: 190
A43: 088940 | B43: PILETA UNIVERZALNA BIJELA 5/4 | E43: 189 | F43: 188
A44: 15010 | B44: KUTNI PROFIL ZA PANELE 5 mm | E44: 187 | F44: 187
A45: 17177 | B45: NERO DRŽAČ WC ČETKE - CRNI | C45: 6458 | D45: BOJIA TRADING LIMITED | E45: 186 | F45: 186
A46: 15011 | B46: ZAVRŠNI PROFIL ZA PANELE 5 mm | E46: 184 | F46: 184
A47: 18242 | B47: GEA OGLEDALO D80 cm | C47: 6032 | D47: HANGZHOU ZIHAN MIRROR INDUSTRY CO., LTD. | E47: 170 | F47: 170
A48: 046200 | B48: ZELENA OBLOGA ZA ZID VERDE SELVA | C48: 6931 | D48: INTCO INTERNATIONAL (HK) CO., LIMITED | E48: 165 | F48: 165
A49: 00897 | B49: LYNN OGLEDALO S LED RASVJETOM 60x80 cm | C49: 5720 | D49: ZHEJIANG SUMMERSIDE SANITARY WARE TECHNOLOGY CO., LTD | E49: 169 | F49: 161
A50: 16855 | B50: MOHO WC MONOBLOK ZIDNI ODVOD 665x375x725 mm | E50: 161 | F50: 161
A51: 18241 | B51: GEA OGLEDALO D70 cm | C51: 6032 | D51: HANGZHOU ZIHAN MIRROR INDUSTRY CO., LTD. | E51: 170 | F51: 161
A52: 003977 | B52: VERONA 3u1 SET MIJEŠALICA | C52: 4053 | D52: TAIZHOU ZHENGSHING VALVE CO .,LTD | E52: 157 | F52: 157
A53: 17180 | B53: REFLECT DRŽAČ TOALETNOG PAPIRA - KROM | C53: 6458 | D53: BOJIA TRADING LIMITED | E53: 149 | F53: 149
A54: 18245 | B54: ZOYA GOLD OGLEDALO R 60 cm | C54: 6032 | D54: HANGZHOU ZIHAN MIRROR INDUSTRY CO., LTD. | E54: 147 | F54: 146
A55: 088941 | B55: PILETA UNIVERZALNA CRNA 5/4 | E55: 142 | F55: 142
A56: 17192 | B56: QUADRA VISEĆA ŠKOLJKA S DASKOM RIMLESS 510x350x360 mm | E56: 141 | F56: 141
A57: 042127C | B57: SHINE C DIA 60 cm LED OGLEDALO SA SENZOROM POKRETA | C57: 6032 | D57: HANGZHOU ZIHAN MIRROR INDUSTRY CO., LTD. | E57: 142 | F57: 140
A58: 18732 | B58: MONDO L VISEĆA ŠKOLJKA S DASKOM - VORTEX 520x360x350 mm | C58: 7080 | D58: TANGSHAN KARCENT CERAMIC CO.,LTD | E58: 137 | F58: 137
A59: 002337 | B59: ESSEN MIJEŠALICA ZA KADU | C59: 6022 | D59: RUIAN HAIBA SANITARY CO.,LTD | E59: 133 | F59: 133
...

Sheet PODACI_PRODAJA
A1: Artikal | B1: Siječanj | C1: Veljača | D1: Ožujak | E1: Travanj | F1: Svibanj | G1: Lipanj | H1: Srpanj | I1: Kolovoz | J1: Rujan | K1: Listopad | L1: Studeni | M1: Prosinac | N1: Prosjek/mj.
A2: 00836 | B2: 195 | C2: 251 | D2: 334 | E2: 325 | F2: 183 | G2: 276 | H2: 303 | I2: 245 | J2: 103 | K2: 0 | L2: 0 | M2: 0 | N2: =IFERROR(ROUND(SUM(OFFSET(B2,0,0,1,POSTAVKE!$B$7))/POSTAVKE!$B$7,2),0) -> 264
A3: 00835 | B3: 134 | C3: 73 | D3: 121 | E3: 121 | F3: 77 | G3: 108 | H3: 145 | I3: 97 | J3: 47 | K3: 0 | L3: 0 | M3: 0 | N3: =IFERROR(ROUND(SUM(OFFSET(B3,0,0,1,POSTAVKE!$B$7))/POSTAVKE!$B$7,2),0) -> 109.5
A4: 00834 | B4: 125 | C4: 102 | D4: 129 | E4: 124 | F4: 96 | G4: 154 | H4: 157 | I4: 121 | J4: 36 | K4: 0 | L4: 0 | M4: 0 | N4: =IFERROR(ROUND(SUM(OFFSET(B4,0,0,1,POSTAVKE!$B$7))/POSTAVKE!$B$7,2),0) -> 126
A5: 00875 | B5: 112 | C5: 196 | D5: 87 | E5: 114 | F5: 114 | G5: 111 | H5: 220 | I5: 206 | J5: 36 | K5: 0 | L5: 0 | M5: 0 | N5: =IFERROR(ROUND(SUM(OFFSET(B5,0,0,1,POSTAVKE!$B$7))/POSTAVKE!$B$7,2),0) -> 145
A6: 00850 | B6: 108 | C6: 58 | D6: 182 | E6: 132 | F6: 118 | G6: 171 | H6: 111 | I6: 108 | J6: 50 | K6: 0 | L6: 0 | M6: 0 | N6: =IFERROR(ROUND(SUM(OFFSET(B6,0,0,1,POSTAVKE!$B$7))/POSTAVKE!$B$7,2),0) -> 123.5
A7: 002499 | B7: 100 | C7: 88 | D7: 145 | E7: 182 | F7: 76 | G7: 15 | H7: 144 | I7: 147 | J7: 76 | K7: 0 | L7: 0 | M7: 0 | N7: =IFERROR(ROUND(SUM(OFFSET(B7,0,0,1,POSTAVKE!$B$7))/POSTAVKE!$B$7,2),0) -> 112.13
A8: 002336 | B8: 80 | C8: 91 | D8: 83 | E8: 131 | F8: 79 | G8: 76 | H8: 79 | I8: 71 | J8: 0 | K8: 0 | L8: 0 | M8: 0 | N8: =IFERROR(ROUND(SUM(OFFSET(B8,0,0,1,POSTAVKE!$B$7))/POSTAVKE!$B$7,2),0) -> 86.25
A9: 15451 | B9: 80 | C9: 42 | D9: 29 | E9: 20 | F9: 59 | G9: 74 | H9: 53 | I9: 56 | J9: 24 | K9: 0 | L9: 0 | M9: 0 | N9: =IFERROR(ROUND(SUM(OFFSET(B9,0,0,1,POSTAVKE!$B$7))/POSTAVKE!$B$7,2),0) -> 51.63
A10: 00837 | B10: 77 | C10: 121 | D10: 138 | E10: 163 | F10: 114 | G10: 126 | H10: 177 | I10: 120 | J10: 0 | K10: 0 | L10: 0 | M10: 0 | N10: =IFERROR(ROUND(SUM(OFFSET(B10,0,0,1,POSTAVKE!$B$7))/POSTAVKE!$B$7,2),0) -> 129.5
A11: 00849 | B11: 70 | C11: 44 | D11: 61 | E11: 54 | F11: 33 | G11: 35 | H11: 45 | I11: 50 | J11: 11 | K11: 0 | L11: 0 | M11: 0 | N11: =IFERROR(ROUND(SUM(OFFSET(B11,0,0,1,POSTAVKE!$B$7))/POSTAVKE!$B$7,2),0) -> 49
A12: 00720 | B12: 66 | C12: 43 | D12: 65 | E12: 80 | F12: 66 | G12: 98 | H12: 141 | I12: 106 | J12: 31 | K12: 0 | L12: 0 | M12: 0 | N12: =IFERROR(ROUND(SUM(OFFSET(B12,0,0,1,POSTAVKE!$B$7))/POSTAVKE!$B$7,2),0) -> 83.13
A13: 003227 | B13: 63 | C13: 36 | D13: 46 | E13: 39 | F13: 46 | G13: 34 | H13: 37 | I13: 40 | J13: 0 | K13: 0 | L13: 0 | M13: 0 | N13: =IFERROR(ROUND(SUM(OFFSET(B13,0,0,1,POSTAVKE!$B$7))/POSTAVKE!$B$7,2),0) -> 42.63
... A829: 827 | B829: 3285 | C829: 3701 | D829: 6689 | E829: 4533 | F829: 3829 | G829: 3762.32 | H829: 4206.4 | I829: 4008 | J829: 669 | K829: 0 | L829: 0 | M829: 0 | N829: =IFERROR(ROUND(SUM(OFFSET(B829,0,0,1,POSTAVKE!$B$7))/POSTAVKE!$B$7,2),0) -> 4251.72

Sheet ROBA_U_DOLASKU
A1: ROBA U DOLASKU
A2: Zuta polja se rucno unose. Do tri dolaska po artiklu.
A3: Mjeseci do dolaska: upisite svoj potvrdjeni podatak. Predlozak je datum narudzbe + tranzit.
A5: Artikal | B5: Kolicina | C5: Mjeseci do dolaska | D5: Ocekivani datum | E5: Sifra dob. | F5: Narudzba | G5: Napomena | H5: Rb.
A6: 002336 | B6: 300 | C6: 2.2 | D6: 46334 | F6: ND_7858 | H6: =IF(A6="","",COUNTIFS($A$6:$A$95,A6,$C$6:$C$95,"<"&C6)+COUNTIFS($A$6:A6,A6,$C$6:C6,C6)) -> 1
A7: 002940 | B7: 100 | C7: 2.2 | D7: 46334 | F7: ND_7858 | H7: =IF(A7="","",COUNTIFS($A$6:$A$95,A7,$C$6:$C$95,"<"&C7)+COUNTIFS($A$6:A7,A7,$C$6:C7,C7)) -> 1
A8: 002941 | B8: 152 | C8: 2.2 | D8: 46334 | F8: ND_7858 | H8: =IF(A8="","",COUNTIFS($A$6:$A$95,A8,$C$6:$C$95,"<"&C8)+COUNTIFS($A$6:A8,A8,$C$6:C8,C8)) -> 1
A9: 003213 | B9: 20 | C9: 1 | D9: 46298 | F9: ND_7821 | H9: =IF(A9="","",COUNTIFS($A$6:$A$95,A9,$C$6:$C$95,"<"&C9)+COUNTIFS($A$6:A9,A9,$C$6:C9,C9)) -> 1
A10: 003227 | B10: 100 | C10: 2.2 | D10: 46334 | F10: ND_7858 | H10: =IF(A10="","",COUNTIFS($A$6:$A$95,A10,$C$6:$C$95,"<"&C10)+COUNTIFS($A$6:A10,A10,$C$6:C10,C10)) -> 1
A11: 00618 | B11: 100 | C11: 2.2 | D11: 46334 | F11: ND_7857 | H11: =IF(A11="","",COUNTIFS($A$6:$A$95,A11,$C$6:$C$95,"<"&C11)+COUNTIFS($A$6:A11,A11,$C$6:C11,C11)) -> 1
A12: 00897 | B12: 200 | C12: 2.2 | D12: 46334 | F12: ND_7857 | H12: =IF(A12="","",COUNTIFS($A$6:$A$95,A12,$C$6:$C$95,"<"&C12)+COUNTIFS($A$6:A12,A12,$C$6:C12,C12)) -> 1
A13: 00898 | B13: 80 | C13: 2.2 | D13: 46334 | F13: ND_7857 | H13: =IF(A13="","",COUNTIFS($A$6:$A$95,A13,$C$6:$C$95,"<"&C13)+COUNTIFS($A$6:A13,A13,$C$6:C13,C13)) -> 1
A14: 037060 | B14: 20 | C14: 1 | D14: 46298 | F14: ND_7821 | H14: =IF(A14="","",COUNTIFS($A$6:$A$95,A14,$C$6:$C$95,"<"&C14)+COUNTIFS($A$6:A14,A14,$C$6:C14,C14)) -> 1
A15: 037080 | B15: 20 | C15: 1 | D15: 46298 | F15: ND_7821 | H15: =IF(A15="","",COUNTIFS($A$6:$A$95,A15,$C$6:$C$95,"<"&C15)+COUNTIFS($A$6:A15,A15,$C$6:C15,C15)) -> 1
A16: 040250 | B16: 20 | C16: 1 | D16: 46298 | F16: ND_7821 | H16: =IF(A16="","",COUNTIFS($A$6:$A$95,A16,$C$6:$C$95,"<"&C16)+COUNTIFS($A$6:A16,A16,$C$6:C16,C16)) -> 1
A17: 041880 | B17: 15 | C17: 1 | D17: 46298 | F17: ND_7821 | H17: =IF(A17="","",COUNTIFS($A$6:$A$95,A17,$C$6:$C$95,"<"&C17)+COUNTIFS($A$6:A17,A17,$C$6:C17,C17)) -> 1
... A52: 18562 | B52: 20 | C52: 1 | D52: 46298 | F52: ND_7821 | H52: =IF(A52="","",COUNTIFS($A$6:$A$95,A52,$C$6:$C$95,"<"&C52)+COUNTIFS($A$6:A52,A52,$C$6:C52,C52)) -> 1
A53: 18658 | B53: 25 | C53: 0.8 | D53: 46293 | F53: ND_7814 | G53: NOVI ARTIKL | H53: =IF(A53="","",COUNTIFS($A$6:$A$95,A53,$C$6:$C$95,"<"&C53)+COUNTIFS($A$6:A53,A53,$C$6:C53,C53)) -> 1
A54: 18659 | B54: 25 | C54: 0.8 | D54: 46293 | F54: ND_7814 | G54: NOVI ARTIKL | H54: =IF(A54="","",COUNTIFS($A$6:$A$95,A54,$C$6:$C$95,"<"&C54)+COUNTIFS($A$6:A54,A54,$C$6:C54,C54)) -> 1
A55: 18660 | B55: 25 | C55: 0.8 | D55: 46293 | F55: ND_7814 | G55: NOVI ARTIKL | H55: =IF(A55="","",COUNTIFS($A$6:$A$95,A55,$C$6:$C$95,"<"&C55)+COUNTIFS($A$6:A55,A55,$C$6:C55,C55)) -> 1
A56: 18665 | B56: 15 | C56: 0.8 | D56: 46293 | F56: ND_7814 | H56: =IF(A56="","",COUNTIFS($A$6:$A$95,A56,$C$6:$C$95,"<"&C56)+COUNTIFS($A$6:A56,A56,$C$6:C56,C56)) -> 1
A57: 18666 | B57: 20 | C57: 0.8 | D57: 46293 | F57: ND_7814 | H57: =IF(A57="","",COUNTIFS($A$6:$A$95,A57,$C$6:$C$95,"<"&C57)+COUNTIFS($A$6:A57,A57,$C$6:C57,C57)) -> 1
A58: 18667 | B58: 15 | C58: 1 | D58: 46298 | F58: ND_7821 | H58: =IF(A58="","",COUNTIFS($A$6:$A$95,A58,$C$6:$C$95,"<"&C58)+COUNTIFS($A$6:A58,A58,$C$6:C58,C58)) -> 1
A59: 18668 | B59: 15 | C59: 1 | D59: 46298 | F59: ND_7821 | H59: =IF(A59="","",COUNTIFS($A$6:$A$95,A59,$C$6:$C$95,"<"&C59)+COUNTIFS($A$6:A59,A59,$C$6:C59,C59)) -> 1
A60: 18762 | B60: 15 | C60: 0.8 | D60: 46293 | F60: ND_7814 | G60: NOVI ARTIKL | H60: =IF(A60="","",COUNTIFS($A$6:$A$95,A60,$C$6:$C$95,"<"&C60)+COUNTIFS($A$6:A60,A60,$C$6:C60,C60)) -> 1
A61: 18763 | B61: 30 | C61: 0.8 | D61: 46293 | F61: ND_7814 | G61: NOVI ARTIKL | H61: =IF(A61="","",COUNTIFS($A$6:$A$95,A61,$C$6:$C$95,"<"&C61)+COUNTIFS($A$6:A61,A61,$C$6:C61,C61)) -> 1
A62: 18764 | B62: 20 | C62: 0.8 | D62: 46293 | F62: ND_7814 | G62: NOVI ARTIKL | H62: =IF(A62="","",COUNTIFS($A$6:$A$95,A62,$C$6:$C$95,"<"&C62)+COUNTIFS($A$6:A62,A62,$C$6:C62,C62)) -> 1
A63: 18765 | B63: 20 | C63: 0.8 | D63: 46293 | F63: ND_7814 | G63: NOVI ARTIKL | H63: =IF(A63="","",COUNTIFS($A$6:$A$95,A63,$C$6:$C$95,"<"&C63)+COUNTIFS($A$6:A63,A63,$C$6:C63,C63)) -> 1
A64: 18766 | B64: 15 | C64: 0.8 | D64: 46293 | F64: ND_7814 | G64: NOVI ARTIKL | H64: =IF(A64="","",COUNTIFS($A$6:$A$95,A64,$C$6:$C$95,"<"&C64)+COUNTIFS($A$6:A64,A64,$C$6:C64,C64)) -> 1
A65: 18767 | B65: 15 | C65: 0.8 | D65: 46293 | F65: ND_7814 | G65: NOVI ARTIKL | H65: =IF(A65="","",COUNTIFS($A$6:$A$95,A65,$C$6:$C$95,"<"&C65)+COUNTIFS($A$6:A65,A65,$C$6:C65,C65)) -> 1
A66: 18768 | B66: 20 | C66: 0.8 | D66: 46293 | F66: ND_7814 | G66: NOVI ARTIKL | H66: =IF(A66="","",COUNTIFS($A$6:$A$95,A66,$C$6:$C$95,"<"&C66)+COUNTIFS($A$6:A66,A66,$C$6:C66,C66)) -> 1
A67: 18769 | B67: 20 | C67: 0.8 | D67: 46293 | F67: ND_7814 | G67: NOVI ARTIKL | H67: =IF(A67="","",COUNTIFS($A$6:$A$95,A67,$C$6:$C$95,"<"&C67)+COUNTIFS($A$6:A67,A67,$C$6:C67,C67)) -> 1
A68: 18770 | B68: 20 | C68: 0.8 | D68: 46293 | F68: ND_7814 | G68: NOVI ARTIKL | H68: =IF(A68="","",COUNTIFS($A$6:$A$95,A68,$C$6:$C$95,"<"&C68)+COUNTIFS($A$6:A68,A68,$C$6:C68,C68)) -> 1
A69: 18771 | B69: 20 | C69: 0.8 | D69: 46293 | F69: ND_7814 | G69: NOVI ARTIKL | H69: =IF(A69="","",COUNTIFS($A$6:$A$95,A69,$C$6:$C$95,"<"&C69)+COUNTIFS($A$6:A69,A69,$C$6:C69,C69)) -> 1
A70: 18772 | B70: 25 | C70: 0.8 | D70: 46293 | F70: ND_7814 | G70: NOVI ARTIKL | H70: =IF(A70="","",COUNTIFS($A$6:$A$95,A70,$C$6:$C$95,"<"&C70)+COUNTIFS($A$6:A70,A70,$C$6:C70,C70)) -> 1
A71: 18773 | B71: 35 | C71: 0.8 | D71: 46293 | F71: ND_7814 | G71: NOVI ARTIKL | H71: =IF(A71="","",COUNTIFS($A$6:$A$95,A71,$C$6:$C$95,"<"&C71)+COUNTIFS($A$6:A71,A71,$C$6:C71,C71)) -> 1
... A75: 18777 | B75: 30 | C75: 1 | D75: 46298 | F75: ND_7821 | G75: NOVI ARTIKL | H75: =IF(A75="","",COUNTIFS($A$6:$A$95,A75,$C$6:$C$95,"<"&C75)+COUNTIFS($A$6:A75,A75,$C$6:C75,C75)) -> 1
H76: =IF(A76="","",COUNTIFS($A$6:$A$95,A76,$C$6:$C$95,"<"&C76)+COUNTIFS($A$6:A76,A76,$C$6:C76,C76))
H77: =IF(A77="","",COUNTIFS($A$6:$A$95,A77,$C$6:$C$95,"<"&C77)+COUNTIFS($A$6:A77,A77,$C$6:C77,C77))
H78: =IF(A78="","",COUNTIFS($A$6:$A$95,A78,$C$6:$C$95,"<"&C78)+COUNTIFS($A$6:A78,A78,$C$6:C78,C78))
...

Sheet NABAVA
A1: NABAVA - planiranje narudžbi
A2: Prag 5 mjeseci · roba na brodu se NE pribraja zalihi · do tri dolaska po artiklu
A4: Šifra | B4: Naziv artikla | C4: Šifra dob. | D4: Naziv dobavljača | E4: Zaliha 31.08. | F4: Zaliha danas | G4: Izlaz od 31.08. | H4: Prosjek/mj. | I4: Zaliha traje (mj.) | J4: Stiže 1 | K4: Količina 1 | L4: Stiže 2 | M4: Količina 2 | N4: Stiže 3 | O4: Količina 3 | P4: Pokrivenost ukupno | Q4: STATUS | S4: Sij | T4: Vel | U4: Ožu | V4: Tra | W4: Svi | X4: Lip | Y4: Srp | Z4: Kol | AA4: Ruj | AB4: Lis | AC4: Stu | AD4: Pro
A5: =PODACI_ZALIHE!A2 -> 16958 | B5: =PODACI_ZALIHE!B2 -> KERAMIČKI OVLAŽIVAČ ZRAKA ZA RADIJATOR 20x8.5x3.5 cm | C5: =PODACI_ZALIHE!C2 -> 0 | D5: =PODACI_ZALIHE!D2 -> 0 | E5: =IF(PODACI_ZALIHE!E2="","",PODACI_ZALIHE!E2) -> 1595 | F5: =PODACI_ZALIHE!F2 -> 1595 | G5: =IF(E5="","",E5-F5) -> 0 | H5: =PODACI_PRODAJA!N258 -> 175.63 | I5: =IF(H5<=0,999,ROUND(F5/H5,1)) -> 9.1 | J5: =SUMIFS(ROBA_U_DOLASKU!$C$6:$C$95,ROBA_U_DOLASKU!$A$6:$A$95,A5,ROBA_U_DOLASKU!$H$6:$H$95,1) -> 0 | K5: =SUMIFS(ROBA_U_DOLASKU!$B$6:$B$95,ROBA_U_DOLASKU!$A$6:$A$95,A5,ROBA_U_DOLASKU!$H$6:$H$95,1) -> 0 | L5: =SUMIFS(ROBA_U_DOLASKU!$C$6:$C$95,ROBA_U_DOLASKU!$A$6:$A$95,A5,ROBA_U_DOLASKU!$H$6:$H$95,2) -> 0 | M5: =SUMIFS(ROBA_U_DOLASKU!$B$6:$B$95,ROBA_U_DOLASKU!$A$6:$A$95,A5,ROBA_U_DOLASKU!$H$6:$H$95,2) -> 0 | N5: =SUMIFS(ROBA_U_DOLASKU!$C$6:$C$95,ROBA_U_DOLASKU!$A$6:$A$95,A5,ROBA_U_DOLASKU!$H$6:$H$95,3) -> 0 | O5: =SUMIFS(ROBA_U_DOLASKU!$B$6:$B$95,ROBA_U_DOLASKU!$A$6:$A$95,A5,ROBA_U_DOLASKU!$H$6:$H$95,3) -> 0 | P5: =IF(H5<=0,999,IF(O5>0,ROUND((F5-H5*N5+K5+M5+O5)/H5,1),IF(M5>0,ROUND((F5-H5*L5+K5+M5)/H5,1),IF(K5>0,ROUND((F5-H5*J5+K5)/H5,1),I5)))) -> 9.1 | Q5: =IF(H5<=0,"Nema prodaje",IF(AND(K5=0,M5=0,O5=0),IF(I5<POSTAVKE!$B$6,"Naruči odmah","Sve u redu"),IF(F5-H5*J5<0,"Rupa za ~"&TEXT(I5,"0.0")&" mj.",IF(AND(M5>0,F5-H5*L5+K5<0),"Rupa nakon 1. dolaska",IF(AND(O5>0,F5-H5*N5+K5+M5<0),"Rupa nakon 2. dolaska",IF(P5<POSTAVKE!$B$6,"Količina nije dovoljna",IF(I5>=POSTAVKE!$B$6,"Sve u redu","Stiže na vrijeme"))))))) -> Sve u redu | S5: =IFERROR(INDEX(PODACI_PRODAJA!B:B,MATCH($A5,PODACI_PRODAJA!$A:$A,0)),0) -> 1 | T5: =IFERROR(INDEX(PODACI_PRODAJA!C:C,MATCH($A5,PODACI_PRODAJA!$A:$A,0)),0) -> -1 | U5: =IFERROR(INDEX(PODACI_PRODAJA!D:D,MATCH($A5,PODACI_PRODAJA!$A:$A,0)),0) -> 1405 | V5: =IFERROR(INDEX(PODACI_PRODAJA!E:E,MATCH($A5,PODACI_PRODAJA!$A:$A,0)),0) -> 0 | W5: =IFERROR(INDEX(PODACI_PRODAJA!F:F,MATCH($A5,PODACI_PRODAJA!$A:$A,0)),0) -> 0 | X5: =IFERROR(INDEX(PODACI_PRODAJA!G:G,MATCH($A5,PODACI_PRODAJA!$A:$A,0)),0) -> 0 | Y5: =IFERROR(INDEX(PODACI_PRODAJA!H:H,MATCH($A5,PODACI_PRODAJA!$A:$A,0)),0) -> 0 | Z5: =IFERROR(INDEX(PODACI_PRODAJA!I:I,MATCH($A5,PODACI_PRODAJA!$A:$A,0)),0) -> 0 | AA5: =IFERROR(INDEX(PODACI_PRODAJA!J:J,MATCH($A5,PODACI_PRODAJA!$A:$A,0)),0) -> 0 | AB5: =IFERROR(INDEX(PODACI_PRODAJA!K:K,MATCH($A5,PODACI_PRODAJA!$A:$A,0)),0) -> 0 | AC5: =IFERROR(INDEX(PODACI_PRODAJA!L:L,MATCH($A5,PODACI_PRODAJA!$A:$A,0)),0) -> 0 | AD5: =IFERROR(INDEX(PODACI_PRODAJA!M:M,MATCH($A5,PODACI_PRODAJA!$A:$A,0)),0) -> 0
A6: =PODACI_ZALIHE!A3 -> 00617 | B6: =PODACI_ZALIHE!B3 -> MIJEŠALICA ZA SUDOPER PROTOČNI BOJLER | C6: =PODACI_ZALIHE!C3 -> 2974 | D6: =PODACI_ZALIHE!D3 -> TAIZHOU MINUOTE SANITARY WARES CO.,LTD. | E6: =IF(PODACI_ZALIHE!E3="","",PODACI_ZALIHE!E3) -> 932 | F6: =PODACI_ZALIHE!F3 -> 932 | G6: =IF(E6="","",E6-F6) -> 0 | H6: =PODACI_PRODAJA!N16 -> 42.38 | I6: =IF(H6<=0,999,ROUND(F6/H6,1)) -> 22 | J6: =SUMIFS(ROBA_U_DOLASKU!$C$6:$C$95,ROBA_U_DOLASKU!$A$6:$A$95,A6,ROBA_U_DOLASKU!$H$6:$H$95,1) -> 0 | K6: =SUMIFS(ROBA_U_DOLASKU!$B$6:$B$95,ROBA_U_DOLASKU!$A$6:$A$95,A6,ROBA_U_DOLASKU!$H$6:$H$95,1) -> 0 | L6: =SUMIFS(ROBA_U_DOLASKU!$C$6:$C$95,ROBA_U_DOLASKU!$A$6:$A$95,A6,ROBA_U_DOLASKU!$H$6:$H$95,2) -> 0 | M6: =SUMIFS(ROBA_U_DOLASKU!$B$6:$B$95,ROBA_U_DOLASKU!$A$6:$A$95,A6,ROBA_U_DOLASKU!$H$6:$H$95,2) -> 0 | N6: =SUMIFS(ROBA_U_DOLASKU!$C$6:$C$95,ROBA_U_DOLASKU!$A$6:$A$95,A6,ROBA_U_DOLASKU!$H$6:$H$95,3) -> 0 | O6: =SUMIFS(ROBA_U_DOLASKU!$B$6:$B$95,ROBA_U_DOLASKU!$A$6:$A$95,A6,ROBA_U_DOLASKU!$H$6:$H$95,3) -> 0 | P6: =IF(H6<=0,999,IF(O6>0,ROUND((F6-H6*N6+K6+M6+O6)/H6,1),IF(M6>0,ROUND((F6-H6*L6+K6+M6)/H6,1),IF(K6>0,ROUND((F6-H6*J6+K6)/H6,1),I6)))) -> 22 | Q6: =IF(H6<=0,"Nema prodaje",IF(AND(K6=0,M6=0,O6=0),IF(I6<POSTAVKE!$B$6,"Naruči odmah","Sve u redu"),IF(F6-H6*J6<0,"Rupa za ~"&TEXT(I6,"0.0")&" mj.",IF(AND(M6>0,F6-H6*L6+K6<0),"Rupa nakon 1. dolaska",IF(AND(O6>0,F6-H6*N6+K6+M6<0),"Rupa nakon 2. dolaska",IF(P6<POSTAVKE!$B$6,"Količina nije dovoljna",IF(I6>=POSTAVKE!$B$6,"Sve u redu","Stiže na vrijeme"))))))) -> Sve u redu | S6: =IFERROR(INDEX(PODACI_PRODAJA!B:B,MATCH($A6,PODACI_PRODAJA!$A:$A,0)),0) -> 50 | T6: =IFERROR(INDEX(PODACI_PRODAJA!C:C,MATCH($A6,PODACI_PRODAJA!$A:$A,0)),0) -> 36 | U6: =IFERROR(INDEX(PODACI_PRODAJA!D:D,MATCH($A6,PODACI_PRODAJA!$A:$A,0)),0) -> 40 | V6: =IFERROR(INDEX(PODACI_PRODAJA!E:E,MATCH($A6,PODACI_PRODAJA!$A:$A,0)),0) -> 34 | W6: =IFERROR(INDEX(PODACI_PRODAJA!F:F,MATCH($A6,PODACI_PRODAJA!$A:$A,0)),0) -> 45 | X6: =IFERROR(INDEX(PODACI_PRODAJA!G:G,MATCH($A6,PODACI_PRODAJA!$A:$A,0)),0) -> 41 | Y6: =IFERROR(INDEX(PODACI_PRODAJA!H:H,MATCH($A6,PODACI_PRODAJA!$A:$A,0)),0) -> 52 | Z6: =IFERROR(INDEX(PODACI_PRODAJA!I:I,MATCH($A6,PODACI_PRODAJA!$A:$A,0)),0) -> 41 | AA6: =IFERROR(INDEX(PODACI_PRODAJA!J:J,MATCH($A6,PODACI_PRODAJA!$A:$A,0)),0) -> 0 | AB6: =IFERROR(INDEX(PODACI_PRODAJA!K:K,MATCH($A6,PODACI_PRODAJA!$A:$A,0)),0) -> 0 | AC6: =IFERROR(INDEX(PODACI_PRODAJA!L:L,MATCH($A6,PODACI_PRODAJA!$A:$A,0)),0) -> 0 | AD6: =IFERROR(INDEX(PODACI_PRODAJA!M:M,MATCH($A6,PODACI_PRODAJA!$A:$A,0)),0) -> 0
A7: =PODACI_ZALIHE!A4 -> 00836 | B7: =PODACI_ZALIHE!B4 -> GL11428 SIFON ZA TUŠ KADU LUX 60 mm | C7: =PODACI_ZALIHE!C4 -> 3291 | D7: =PODACI_ZALIHE!D4 -> TEHNOEXPORT D.O.O. | E7: =IF(PODACI_ZALIHE!E4="","",PODACI_ZALIHE!E4) -> 664 | F7: =PODACI_ZALIHE!F4 -> 561 | G7: =IF(E7="","",E7-F7) -> 103 | H7: =PODACI_PRODAJA!N2 -> 264 | I7: =IF(H7<=0,999,ROUND(F7/H7,1)) -> 2.1 | J7: =SUMIFS(ROBA_U_DOLASKU!$C$6:$C$95,ROBA_U_DOLASKU!$A$6:$A$95,A7,ROBA_U_DOLASKU!$H$6:$H$95,1) -> 0 | K7: =SUMIFS(ROBA_U_DOLASKU!$B$6:$B$95,ROBA_U_DOLASKU!$A$6:$A$95,A7,ROBA_U_DOLASKU!$H$6:$H$95,1) -> 0 | L7: =SUMIFS(ROBA_U_DOLASKU!$C$6:$C$95,ROBA_U_DOLASKU!$A$6:$A$95,A7,ROBA_U_DOLASKU!$H$6:$H$95,2) -> 0 | M7: =SUMIFS(ROBA_U_DOLASKU!$B$6:$B$95,ROBA_U_DOLASKU!$A$6:$A$95,A7,ROBA_U_DOLASKU!$H$6:$H$95,2) -> 0 | N7: =SUMIFS(ROBA_U_DOLASKU!$C$6:$C$95,ROBA_U_DOLASKU!$A$6:$A$95,A7,ROBA_U_DOLASKU!$H$6:$H$95,3) -> 0 | O7: =SUMIFS(ROBA_U_DOLASKU!$B$6:$B$95,ROBA_U_DOLASKU!$A$6:$A$95,A7,ROBA_U_DOLASKU!$H$6:$H$95,3) -> 0 | P7: =IF(H7<=0,999,IF(O7>0,ROUND((F7-H7*N7+K7+M7+O7)/H7,1),IF(M7>0,ROUND((F7-H7*L7+K7+M7)/H7,1),IF(K7>0,ROUND((F7-H7*J7+K7)/H7,1),I7)))) -> 2.1 | Q7: =IF(H7<=0,"Nema prodaje",IF(AND(K7=0,M7=0,O7=0),IF(I7<POSTAVKE!$B$6,"Naruči odmah","Sve u redu"),IF(F7-H7*J7<0,"Rupa za ~"&TEXT(I7,"0.0")&" mj.",IF(AND(M7>0,F7-H7*L7+K7<0),"Rupa nakon 1. dolaska",IF(AND(O7>0,F7-H7*N7+K7+M7<0),"Rupa nakon 2. dolaska",IF(P7<POSTAVKE!$B$6,"Količina nije dovoljna",IF(I7>=POSTAVKE!$B$6,"Sve u redu","Stiže na vrijeme"))))))) -> Naruči odmah | S7: =IFERROR(INDEX(PODACI_PRODAJA!B:B,MATCH($A7,PODACI_PRODAJA!$A:$A,0)),0) -> 195 | T7: =IFERROR(INDEX(PODACI_PRODAJA!C:C,MATCH($A7,PODACI_PRODAJA!$A:$A,0)),0) -> 251 | U7: =IFERROR(INDEX(PODACI_PRODAJA!D:D,MATCH($A7,PODACI_PRODAJA!$A:$A,0)),0) -> 334 | V7: =IFERROR(INDEX(PODACI_PRODAJA!E:E,MATCH($A7,PODACI_PRODAJA!$A:$A,0)),0) -> 325 | W7: =IFERROR(INDEX(PODACI_PRODAJA!F:F,MATCH($A7,PODACI_PRODAJA!$A:$A,0)),0) -> 183 | X7: =IFERROR(INDEX(PODACI_PRODAJA!G:G,MATCH($A7,PODACI_PRODAJA!$A:$A,0)),0) -> 276 | Y7: =IFERROR(INDEX(PODACI_PRODAJA!H:H,MATCH($A7,PODACI_PRODAJA!$A:$A,0)),0) -> 303 | Z7: =IFERROR(INDEX(PODACI_PRODAJA!I:I,MATCH($A7,PODACI_PRODAJA!$A:$A,0)),0) -> 245 | AA7: =IFERROR(INDEX(PODACI_PRODAJA!J:J,MATCH($A7,PODACI_PRODAJA!$A:$A,0)),0) -> 103 | AB7: =IFERROR(INDEX(PODACI_PRODAJA!K:K,MATCH($A7,PODACI_PRODAJA!$A:$A,0)),0) -> 0 | AC7: =IFERROR(INDEX(PODACI_PRODAJA!L:L,MATCH($A7,PODACI_PRODAJA!$A:$A,0)),0) -> 0 | AD7: =IFERROR(INDEX(PODACI_PRODAJA!M:M,MATCH($A7,PODACI_PRODAJA!$A:$A,0)),0) -> 0
A8: =PODACI_ZALIHE!A5 -> 16856 | B8: =PODACI_ZALIHE!B5 -> MOHO WC MONOBLOK PODNI ODVOD 665x375x725 mm | C8: =PODACI_ZALIHE!C5 -> 0 | D8: =PODACI_ZALIHE!D5 -> 0 | E8: =IF(PODACI_ZALIHE!E5="","",PODACI_ZALIHE!E5) -> 526 | F8: =PODACI_ZALIHE!F5 -> 526 | G8: =IF(E8="","",E8-F8) -> 0 | H8: =PODACI_PRODAJA!N203 -> 3.88 | I8: =IF(H8<=0,999,ROUND(F8/H8,1)) -> 135.6 | J8: =SUMIFS(ROBA_U_DOLASKU!$C$6:$C$95,ROBA_U_DOLASKU!$A$6:$A$95,A8,ROBA_U_DOLASKU!$H$6:$H$95,1) -> 0 | K8: =SUMIFS(ROBA_U_DOLASKU!$B$6:$B$95,ROBA_U_DOLASKU!$A$6:$A$95,A8,ROBA_U_DOLASKU!$H$6:$H$95,1) -> 0 | L8: =SUMIFS(ROBA_U_DOLASKU!$C$6:$C$95,ROBA_U_DOLASKU!$A$6:$A$95,A8,ROBA_U_DOLASKU!$H$6:$H$95,2) -> 0 | M8: =SUMIFS(ROBA_U_DOLASKU!$B$6:$B$95,ROBA_U_DOLASKU!$A$6:$A$95,A8,ROBA_U_DOLASKU!$H$6:$H$95,2) -> 0 | N8: =SUMIFS(ROBA_U_DOLASKU!$C$6:$C$95,ROBA_U_DOLASKU!$A$6:$A$95,A8,ROBA_U_DOLASKU!$H$6:$H$95,3) -> 0 | O8: =SUMIFS(ROBA_U_DOLASKU!$B$6:$B$95,ROBA_U_DOLASKU!$A$6:$A$95,A8,ROBA_U_DOLASKU!$H$6:$H$95,3) -> 0 | P8: =IF(H8<=0,999,IF(O8>0,ROUND((F8-H8*N8+K8+M8+O8)/H8,1),IF(M8>0,ROUND((F8-H8*L8+K8+M8)/H8,1),IF(K8>0,ROUND((F8-H8*J8+K8)/H8,1),I8)))) -> 135.6 | Q8: =IF(H8<=0,"Nema prodaje",IF(AND(K8=0,M8=0,O8=0),IF(I8<POSTAVKE!$B$6,"Naruči odmah","Sve u redu"),IF(F8-H8*J8<0,"Rupa za ~"&TEXT(I8,"0.0")&" mj.",IF(AND(M8>0,F8-H8*L8+K8<0),"Rupa nakon 1. dolaska",IF(AND(O8>0,F8-H8*N8+K8+M8<0),"Rupa nakon 2. dolaska",IF(P8<POSTAVKE!$B$6,"Količina nije dovoljna",IF(I8>=POSTAVKE!$B$6,"Sve u redu","Stiže na vrijeme"))))))) -> Sve u redu | S8: =IFERROR(INDEX(PODACI_PRODAJA!B:B,MATCH($A8,PODACI_PRODAJA!$A:$A,0)),0) -> 2 | T8: =IFERROR(INDEX(PODACI_PRODAJA!C:C,MATCH($A8,PODACI_PRODAJA!$A:$A,0)),0) -> 14 | U8: =IFERROR(INDEX(PODACI_PRODAJA!D:D,MATCH($A8,PODACI_PRODAJA!$A:$A,0)),0) -> 1 | V8: =IFERROR(INDEX(PODACI_PRODAJA!E:E,MATCH($A8,PODACI_PRODAJA!$A:$A,0)),0) -> 4 | W8: =IFERROR(INDEX(PODACI_PRODAJA!F:F,MATCH($A8,PODACI_PRODAJA!$A:$A,0)),0) -> 9 | X8: =IFERROR(INDEX(PODACI_PRODAJA!G:G,MATCH($A8,PODACI_PRODAJA!$A:$A,0)),0) -> 0 | Y8: =IFERROR(INDEX(PODACI_PRODAJA!H:H,MATCH($A8,PODACI_PRODAJA!$A:$A,0)),0) -> 0 | Z8: =IFERROR(INDEX(PODACI_PRODAJA!I:I,MATCH($A8,PODACI_PRODAJA!$A:$A,0)),0) -> 1 | AA8: =IFERROR(INDEX(PODACI_PRODAJA!J:J,MATCH($A8,PODACI_PRODAJA!$A:$A,0)),0) -> 0 | AB8: =IFERROR(INDEX(PODACI_PRODAJA!K:K,MATCH($A8,PODACI_PRODAJA!$A:$A,0)),0) -> 0 | AC8: =IFERROR(INDEX(PODACI_PRODAJA!L:L,MATCH($A8,PODACI_PRODAJA!$A:$A,0)),0) -> 0 | AD8: =IFERROR(INDEX(PODACI_PRODAJA!M:M,MATCH($A8,PODACI_PRODAJA!$A:$A,0)),0) -> 0
A9: =PODACI_ZALIHE!A6 -> 18749 | B9: =PODACI_ZALIHE!B6 -> ZIDNI PANEL PVC NATURAL HRAST 3000x200x5 mm | C9: =PODACI_ZALIHE!C6 -> 6931 | D9: =PODACI_ZALIHE!D6 -> INTCO INTERNATIONAL (HK) CO., LIMITED | E9: =IF(PODACI_ZALIHE!E6="","",PODACI_ZALIHE!E6) -> 504 | F9: =PODACI_ZALIHE!F6 -> 503 | G9: =IF(E9="","",E9-F9) -> 1 | H9: =PODACI_PRODAJA!N704 -> 0 | I9: =IF(H9<=0,999,ROUND(F9/H9,1)) -> 999 | J9: =SUMIFS(ROBA_U_DOLASKU!$C$6:$C$95,ROBA_U_DOLASKU!$A$6:$A$95,A9,ROBA_U_DOLASKU!$H$6:$H$95,1) -> 0 | K9: =SUMIFS(ROBA_U_DOLASKU!$B$6:$B$95,ROBA_U_DOLASKU!$A$6:$A$95,A9,ROBA_U_DOLASKU!$H$6:$H$95,1) -> 0 | L9: =SUMIFS(ROBA_U_DOLASKU!$C$6:$C$95,ROBA_U_DOLASKU!$A$6:$A$95,A9,ROBA_U_DOLASKU!$H$6:$H$95,2) -> 0 | M9: =SUMIFS(ROBA_U_DOLASKU!$B$6:$B$95,ROBA_U_DOLASKU!$A$6:$A$95,A9,ROBA_U_DOLASKU!$H$6:$H$95,2) -> 0 | N9: =SUMIFS(ROBA_U_DOLASKU!$C$6:$C$95,ROBA_U_DOLASKU!$A$6:$A$95,A9,ROBA_U_DOLASKU!$H$6:$H$95,3) -> 0 | O9: =SUMIFS(ROBA_U_DOLASKU!$B$6:$B$95,ROBA_U_DOLASKU!$A$6:$A$95,A9,ROBA_U_DOLASKU!$H$6:$H$95,3) -> 0 | P9: =IF(H9<=0,999,IF(O9>0,ROUND((F9-H9*N9+K9+M9+O9)/H9,1),IF(M9>0,ROUND((F9-H9*L9+K9+M9)/H9,1),IF(K9>0,ROUND((F9-H9*J9+K9)/H9,1),I9)))) -> 999 | Q9: =IF(H9<=0,"Nema prodaje",IF(AND(K9=0,M9=0,O9=0),IF(I9<POSTAVKE!$B$6,"Naruči odmah","Sve u redu"),IF(F9-H9*J9<0,"Rupa za ~"&TEXT(I9,"0.0")&" mj.",IF(AND(M9>0,F9-H9*L9+K9<0),"Rupa nakon 1. dolaska",IF(AND(O9>0,F9-H9*N9+K9+M9<0),"Rupa nakon 2. dolaska",IF(P9<POSTAVKE!$B$6,"Količina nije dovoljna",IF(I9>=POSTAVKE!$B$6,"Sve u redu","Stiže na vrijeme"))))))) -> Nema prodaje | S9: =IFERROR(INDEX(PODACI_PRODAJA!B:B,MATCH($A9,PODACI_PRODAJA!$A:$A,0)),0) -> 0 | T9: =IFERROR(INDEX(PODACI_PRODAJA!C:C,MATCH($A9,PODACI_PRODAJA!$A:$A,0)),0) -> 0 | U9: =IFERROR(INDEX(PODACI_PRODAJA!D:D,MATCH($A9,PODACI_PRODAJA!$A:$A,0)),0) -> 0 | V9: =IFERROR(INDEX(PODACI_PRODAJA!E:E,MATCH($A9,PODACI_PRODAJA!$A:$A,0)),0) -> 0 | W9: =IFERROR(INDEX(PODACI_PRODAJA!F:F,MATCH($A9,PODACI_PRODAJA!$A:$A,0)),0) -> 0 | X9: =IFERROR(INDEX(PODACI_PRODAJA!G:G,MATCH($A9,PODACI_PRODAJA!$A:$A,0)),0) -> 0 | Y9: =IFERROR(INDEX(PODACI_PRODAJA!H:H,MATCH($A9,PODACI_PRODAJA!$A:$A,0)),0) -> 0 | Z9: =IFERROR(INDEX(PODACI_PRODAJA!I:I,MATCH($A9,PODACI_PRODAJA!$A:$A,0)),0) -> 0 | AA9: =IFERROR(INDEX(PODACI_PRODAJA!J:J,MATCH($A9,PODACI_PRODAJA!$A:$A,0)),0) -> 0 | AB9: =IFERROR(INDEX(PODACI_PRODAJA!K:K,MATCH($A9,PODACI_PRODAJA!$A:$A,0)),0) -> 0 | AC9: =IFERROR(INDEX(PODACI_PRODAJA!L:L,MATCH($A9,PODACI_PRODAJA!$A:$A,0)),0) -> 0 | AD9: =IFERROR(INDEX(PODACI_PRODAJA!M:M,MATCH($A9,PODACI_PRODAJA!$A:$A,0)),0) -> 0
A10: =PODACI_ZALIHE!A7 -> 00875 | B10: =PODACI_ZALIHE!B7 -> SET KOTAČIĆA ZA TUŠ KABINE 4/1 SW | C10: =PODACI_ZALIHE!C7 -> 4328 | D10: =PODACI_ZALIHE!D7 -> HANGZHOU DUHUI IMPORT AND EXPORT CO.,LTD | E10: =IF(PODACI_ZALIHE!E7="","",PODACI_ZALIHE!E7) -> 540 | F10: =PODACI_ZALIHE!F7 -> 500 | G10: =IF(E10="","",E10-F10) -> 40 | H10: =PODACI_PRODAJA!N5 -> 145 | I10: =IF(H10<=0,999,ROUND(F10/H10,1)) -> 3.4 | J10: =SUMIFS(ROBA_U_DOLASKU!$C$6:$C$95,ROBA_U_DOLASKU!$A$6:$A$95,A10,ROBA_U_DOLASKU!$H$6:$H$95,1) -> 0 | K10: =SUMIFS(ROBA_U_DOLASKU!$B$6:$B$95,ROBA_U_DOLASKU!$A$6:$A$95,A10,ROBA_U_DOLASKU!$H$6:$H$95,1) -> 0 | L10: =SUMIFS(ROBA_U_DOLASKU!$C$6:$C$95,ROBA_U_DOLASKU!$A$6:$A$95,A10,ROBA_U_DOLASKU!$H$6:$H$95,2) -> 0 | M10: =SUMIFS(ROBA_U_DOLASKU!$B$6:$B$95,ROBA_U_DOLASKU!$A$6:$A$95,A10,ROBA_U_DOLASKU!$H$6:$H$95,2) -> 0 | N10: =SUMIFS(ROBA_U_DOLASKU!$C$6:$C$95,ROBA_U_DOLASKU!$A$6:$A$95,A10,ROBA_U_DOLASKU!$H$6:$H$95,3) -> 0 | O10: =SUMIFS(ROBA_U_DOLASKU!$B$6:$B$95,ROBA_U_DOLASKU!$A$6:$A$95,A10,ROBA_U_DOLASKU!$H$6:$H$95,3) -> 0 | P10: =IF(H10<=0,999,IF(O10>0,ROUND((F10-H10*N10+K10+M10+O10)/H10,1),IF(M10>0,ROUND((F10-H10*L10+K10+M10)/H10,1),IF(K10>0,ROUND((F10-H10*J10+K10)/H10,1),I10)))) -> 3.4 | Q10: =IF(H10<=0,"Nema prodaje",IF(AND(K10=0,M10=0,O10=0),IF(I10<POSTAVKE!$B$6,"Naruči odmah","Sve u redu"),IF(F10-H10*J10<0,"Rupa za ~"&TEXT(I10,"0.0")&" mj.",IF(AND(M10>0,F10-H10*L10+K10<0),"Rupa nakon 1. dolaska",IF(AND(O10>0,F10-H10*N10+K10+M10<0),"Rupa nakon 2. dolaska",IF(P10<POSTAVKE!$B$6,"Količina nije dovoljna",IF(I10>=POSTAVKE!$B$6,"Sve u redu","Stiže na vrijeme"))))))) -> Naruči odmah | S10: =IFERROR(INDEX(PODACI_PRODAJA!B:B,MATCH($A10,PODACI_PRODAJA!$A:$A,0)),0) -> 112 | T10: =IFERROR(INDEX(PODACI_PRODAJA!C:C,MATCH($A10,PODACI_PRODAJA!$A:$A,0)),0) -> 196 | U10: =IFERROR(INDEX(PODACI_PRODAJA!D:D,MATCH($A10,PODACI_PRODAJA!$A:$A,0)),0) -> 87 | V10: =IFERROR(INDEX(PODACI_PRODAJA!E:E,MATCH($A10,PODACI_PRODAJA!$A:$A,0)),0) -> 114 | W10: =IFERROR(INDEX(PODACI_PRODAJA!F:F,MATCH($A10,PODACI_PRODAJA!$A:$A,0)),0) -> 114 | X10: =IFERROR(INDEX(PODACI_PRODAJA!G:G,MATCH($A10,PODACI_PRODAJA!$A:$A,0)),0) -> 111 | Y10: =IFERROR(INDEX(PODACI_PRODAJA!H:H,MATCH($A10,PODACI_PRODAJA!$A:$A,0)),0) -> 220 | Z10: =IFERROR(INDEX(PODACI_PRODAJA!I:I,MATCH($A10,PODACI_PRODAJA!$A:$A,0)),0) -> 206 | AA10: =IFERROR(INDEX(PODACI_PRODAJA!J:J,MATCH($A10,PODACI_PRODAJA!$A:$A,0)),0) -> 36 | AB10: =IFERROR(INDEX(PODACI_PRODAJA!K:K,MATCH($A10,PODACI_PRODAJA!$A:$A,0)),0) -> 0 | AC10: =IFERROR(INDEX(PODACI_PRODAJA!L:L,MATCH($A10,PODACI_PRODAJA!$A:$A,0)),0) -> 0 | AD10: =IFERROR(INDEX(PODACI_PRODAJA!M:M,MATCH($A10,PODACI_PRODAJA!$A:$A,0)),0) -> 0
A11: =PODACI_ZALIHE!A8 -> 044450 | B11: =PODACI_ZALIHE!B8 -> SIFON ZA UMIVAONIK 5/4 CRNI MESING | C11: =PODACI_ZALIHE!C8 -> 4826 | D11: =PODACI_ZALIHE!D8 -> TAIZHOU NIXI SANITARY WARE CO.,LTD | E11: =IF(PODACI_ZALIHE!E8="","",PODACI_ZALIHE!E8) -> 500 | F11: =PODACI_ZALIHE!F8 -> 500 | G11: =IF(E11="","",E11-F11) -> 0 | H11: =PODACI_PRODAJA!N181 -> 4.5 | I11: =IF(H11<=0,999,ROUND(F11/H11,1)) -> 111.1 | J11: =SUMIFS(ROBA_U_DOLASKU!$C$6:$C$95,ROBA_U_DOLASKU!$A$6:$A$95,A11,ROBA_U_DOLASKU!$H$6:$H$95,1) -> 0 | K11: =SUMIFS(ROBA_U_DOLASKU!$B$6:$B$95,ROBA_U_DOLASKU!$A$6:$A$95,A11,ROBA_U_DOLASKU!$H$6:$H$95,1) -> 0 | L11: =SUMIFS(ROBA_U_DOLASKU!$C$6:$C$95,ROBA_U_DOLASKU!$A$6:$A$95,A11,ROBA_U_DOLASKU!$H$6:$H$95,2) -> 0 | M11: =SUMIFS(ROBA_U_DOLASKU!$B$6:$B$95,ROBA_U_DOLASKU!$A$6:$A$95,A11,ROBA_U_DOLASKU!$H$6:$H$95,2) -> 0 | N11: =SUMIFS(ROBA_U_DOLASKU!$C$6:$C$95,ROBA_U_DOLASKU!$A$6:$A$95,A11,ROBA_U_DOLASKU!$H$6:$H$95,3) -> 0 | O11: =SUMIFS(ROBA_U_DOLASKU!$B$6:$B$95,ROBA_U_DOLASKU!$A$6:$A$95,A11,ROBA_U_DOLASKU!$H$6:$H$95,3) -> 0 | P11: =IF(H11<=0,999,IF(O11>0,ROUND((F11-H11*N11+K11+M11+O11)/H11,1),IF(M11>0,ROUND((F11-H11*L11+K11+M11)/H11,1),IF(K11>0,ROUND((F11-H11*J11+K11)/H11,1),I11)))) -> 111.1 | Q11: =IF(H11<=0,"Nema prodaje",IF(AND(K11=0,M11=0,O11=0),IF(I11<POSTAVKE!$B$6,"Naruči odmah","Sve u redu"),IF(F11-H11*J11<0,"Rupa za ~"&TEXT(I11,"0.0")&" mj.",IF(AND(M11>0,F11-H11*L11+K11<0),"Rupa nakon 1. dolaska",IF(AND(O11>0,F11-H11*N11+K11+M11<0),"Rupa nakon 2. dolaska",IF(P11<POSTAVKE!$B$6,"Količina nije dovoljna",IF(I11>=POSTAVKE!$B$6,"Sve u redu","Stiže na vrijeme"))))))) -> Sve u redu | S11: =IFERROR(INDEX(PODACI_PRODAJA!B:B,MATCH($A11,PODACI_PRODAJA!$A:$A,0)),0) -> 2 | T11: =IFERROR(INDEX(PODACI_PRODAJA!C:C,MATCH($A11,PODACI_PRODAJA!$A:$A,0)),0) -> 1 | U11: =IFERROR(INDEX(PODACI_PRODAJA!D:D,MATCH($A11,PODACI_PRODAJA!$A:$A,0)),0) -> 5 | V11: =IFERROR(INDEX(PODACI_PRODAJA!E:E,MATCH($A11,PODACI_PRODAJA!$A:$A,0)),0) -> 11 | W11: =IFERROR(INDEX(PODACI_PRODAJA!F:F,MATCH($A11,PODACI_PRODAJA!$A:$A,0)),0) -> 9 | X11: =IFERROR(INDEX(PODACI_PRODAJA!G:G,MATCH($A11,PODACI_PRODAJA!$A:$A,0)),0) -> 5 | Y11: =IFERROR(INDEX(PODACI_PRODAJA!H:H,MATCH($A11,PODACI_PRODAJA!$A:$A,0)),0) -> 3 | Z11: =IFERROR(INDEX(PODACI_PRODAJA!I:I,MATCH($A11,PODACI_PRODAJA!$A:$A,0)),0) -> 0 | AA11: =IFERROR(INDEX(PODACI_PRODAJA!J:J,MATCH($A11,PODACI_PRODAJA!$A:$A,0)),0) -> 0 | AB11: =IFERROR(INDEX(PODACI_PRODAJA!K:K,MATCH($A11,PODACI_PRODAJA!$A:$A,0)),0) -> 0 | AC11: =IFERROR(INDEX(PODACI_PRODAJA!L:L,MATCH($A11,PODACI_PRODAJA!$A:$A,0)),0) -> 0 | AD11: =IFERROR(INDEX(PODACI_PRODAJA!M:M,MATCH($A11,PODACI_PRODAJA!$A:$A,0)),0) -> 0
A12: =PODACI_ZALIHE!A9 -> 00893 | B12: =PODACI_ZALIHE!B9 -> GLA011 PILETA ZA UMIVAONIK 5/4 | C12: =PODACI_ZALIHE!C9 -> 2974 | D12: =PODACI_ZALIHE!D9 -> TAIZHOU MINUOTE SANITARY WARES CO.,LTD. | E12: =IF(PODACI_ZALIHE!E9="","",PODACI_ZALIHE!E9) -> 489 | F12: =PODACI_ZALIHE!F9 -> 479 | G12: =IF(E12="","",E12-F12) -> 10 | H12: =PODACI_PRODAJA!N44 -> 36.88 | I12: =IF(H12<=0,999,ROUND(F12/H12,1)) -> 13 | J12: =SUMIFS(ROBA_U_DOLASKU!$C$6:$C$95,ROBA_U_DOLASKU!$A$6:$A$95,A12,ROBA_U_DOLASKU!$H$6:$H$95,1) -> 0 | K12: =SUMIFS(ROBA_U_DOLASKU!$B$6:$B$95,ROBA_U_DOLASKU!$A$6:$A$95,A12,ROBA_U_DOLASKU!$H$6:$H$95,1) -> 0 | L12: =SUMIFS(ROBA_U_DOLASKU!$C$6:$C$95,ROBA_U_DOLASKU!$A$6:$A$95,A12,ROBA_U_DOLASKU!$H$6:$H$95,2) -> 0 | M12: =SUMIFS(ROBA_U_DOLASKU!$B$6:$B$95,ROBA_U_DOLASKU!$A$6:$A$95,A12,ROBA_U_DOLASKU!$H$6:$H$95,2) -> 0 | N12: =SUMIFS(ROBA_U_DOLASKU!$C$6:$C$95,ROBA_U_DOLASKU!$A$6:$A$95,A12,ROBA_U_DOLASKU!$H$6:$H$95,3) -> 0 | O12: =SUMIFS(ROBA_U_DOLASKU!$B$6:$B$95,ROBA_U_DOLASKU!$A$6:$A$95,A12,ROBA_U_DOLASKU!$H$6:$H$95,3) -> 0 | P12: =IF(H12<=0,999,IF(O12>0,ROUND((F12-H12*N12+K12+M12+O12)/H12,1),IF(M12>0,ROUND((F12-H12*L12+K12+M12)/H12,1),IF(K12>0,ROUND((F12-H12*J12+K12)/H12,1),I12)))) -> 13 | Q12: =IF(H12<=0,"Nema prodaje",IF(AND(K12=0,M12=0,O12=0),IF(I12<POSTAVKE!$B$6,"Naruči odmah","Sve u redu"),IF(F12-H12*J12<0,"Rupa za ~"&TEXT(I12,"0.0")&" mj.",IF(AND(M12>0,F12-H12*L12+K12<0),"Rupa nakon 1. dolaska",IF(AND(O12>0,F12-H12*N12+K12+M12<0),"Rupa nakon 2. dolaska",IF(P12<POSTAVKE!$B$6,"Količina nije dovoljna",IF(I12>=POSTAVKE!$B$6,"Sve u redu","Stiže na vrijeme"))))))) -> Sve u redu | S12: =IFERROR(INDEX(PODACI_PRODAJA!B:B,MATCH($A12,PODACI_PRODAJA!$A:$A,0)),0) -> 20 | T12: =IFERROR(INDEX(PODACI_PRODAJA!C:C,MATCH($A12,PODACI_PRODAJA!$A:$A,0)),0) -> 43 | U12: =IFERROR(INDEX(PODACI_PRODAJA!D:D,MATCH($A12,PODACI_PRODAJA!$A:$A,0)),0) -> 23 | V12: =IFERROR(INDEX(PODACI_PRODAJA!E:E,MATCH($A12,PODACI_PRODAJA!$A:$A,0)),0) -> 44 | W12: =IFERROR(INDEX(PODACI_PRODAJA!F:F,MATCH($A12,PODACI_PRODAJA!$A:$A,0)),0) -> 20 | X12: =IFERROR(INDEX(PODACI_PRODAJA!G:G,MATCH($A12,PODACI_PRODAJA!$A:$A,0)),0) -> 26 | Y12: =IFERROR(INDEX(PODACI_PRODAJA!H:H,MATCH($A12,PODACI_PRODAJA!$A:$A,0)),0) -> 50 | Z12: =IFERROR(INDEX(PODACI_PRODAJA!I:I,MATCH($A12,PODACI_PRODAJA!$A:$A,0)),0) -> 69 | AA12: =IFERROR(INDEX(PODACI_PRODAJA!J:J,MATCH($A12,PODACI_PRODAJA!$A:$A,0)),0) -> 10 | AB12: =IFERROR(INDEX(PODACI_PRODAJA!K:K,MATCH($A12,PODACI_PRODAJA!$A:$A,0)),0) -> 0 | AC12: =IFERROR(INDEX(PODACI_PRODAJA!L:L,MATCH($A12,PODACI_PRODAJA!$A:$A,0)),0) -> 0 | AD12: =IFERROR(INDEX(PODACI_PRODAJA!M:M,MATCH($A12,PODACI_PRODAJA!$A:$A,0)),0) -> 0
A13: =PODACI_ZALIHE!A10 -> 088939 | B13: =PODACI_ZALIHE!B10 -> PILETA UNIVERZALNA KROM 5/4 | C13: =PODACI_ZALIHE!C10 -> 0 | D13: =PODACI_ZALIHE!D10 -> 0 | E13: =IF(PODACI_ZALIHE!E10="","",PODACI_ZALIHE!E10) -> 453 | F13: =PODACI_ZALIHE!F10 -> 453 | G13: =IF(E13="","",E13-F13) -> 0 | H13: =PODACI_PRODAJA!N38 -> 51 | I13: =IF(H13<=0,999,ROUND(F13/H13,1)) -> 8.9 | J13: =SUMIFS(ROBA_U_DOLASKU!$C$6:$C$95,ROBA_U_DOLASKU!$A$6:$A$95,A13,ROBA_U_DOLASKU!$H$6:$H$95,1) -> 0 | K13: =SUMIFS(ROBA_U_DOLASKU!$B$6:$B$95,ROBA_U_DOLASKU!$A$6:$A$95,A13,ROBA_U_DOLASKU!$H$6:$H$95,1) -> 0 | L13: =SUMIFS(ROBA_U_DOLASKU!$C$6:$C$95,ROBA_U_DOLASKU!$A$6:$A$95,A13,ROBA_U_DOLASKU!$H$6:$H$95,2) -> 0 | M13: =SUMIFS(ROBA_U_DOLASKU!$B$6:$B$95,ROBA_U_DOLASKU!$A$6:$A$95,A13,ROBA_U_DOLASKU!$H$6:$H$95,2) -> 0 | N13: =SUMIFS(ROBA_U_DOLASKU!$C$6:$C$95,ROBA_U_DOLASKU!$A$6:$A$95,A13,ROBA_U_DOLASKU!$H$6:$H$95,3) -> 0 | O13: =SUMIFS(ROBA_U_DOLASKU!$B$6:$B$95,ROBA_U_DOLASKU!$A$6:$A$95,A13,ROBA_U_DOLASKU!$H$6:$H$95,3) -> 0 | P13: =IF(H13<=0,999,IF(O13>0,ROUND((F13-H13*N13+K13+M13+O13)/H13,1),IF(M13>0,ROUND((F13-H13*L13+K13+M13)/H13,1),IF(K13>0,ROUND((F13-H13*J13+K13)/H13,1),I13)))) -> 8.9 | Q13: =IF(H13<=0,"Nema prodaje",IF(AND(K13=0,M13=0,O13=0),IF(I13<POSTAVKE!$B$6,"Naruči odmah","Sve u redu"),IF(F13-H13*J13<0,"Rupa za ~"&TEXT(I13,"0.0")&" mj.",IF(AND(M13>0,F13-H13*L13+K13<0),"Rupa nakon 1. dolaska",IF(AND(O13>0,F13-H13*N13+K13+M13<0),"Rupa nakon 2. dolaska",IF(P13<POSTAVKE!$B$6,"Količina nije dovoljna",IF(I13>=POSTAVKE!$B$6,"Sve u redu","Stiže na vrijeme"))))))) -> Sve u redu | S13: =IFERROR(INDEX(PODACI_PRODAJA!B:B,MATCH($A13,PODACI_PRODAJA!$A:$A,0)),0) -> 25 | T13: =IFERROR(INDEX(PODACI_PRODAJA!C:C,MATCH($A13,PODACI_PRODAJA!$A:$A,0)),0) -> 31 | U13: =IFERROR(INDEX(PODACI_PRODAJA!D:D,MATCH($A13,PODACI_PRODAJA!$A:$A,0)),0) -> 63 | V13: =IFERROR(INDEX(PODACI_PRODAJA!E:E,MATCH($A13,PODACI_PRODAJA!$A:$A,0)),0) -> 58 | W13: =IFERROR(INDEX(PODACI_PRODAJA!F:F,MATCH($A13,PODACI_PRODAJA!$A:$A,0)),0) -> 79 | X13: =IFERROR(INDEX(PODACI_PRODAJA!G:G,MATCH($A13,PODACI_PRODAJA!$A:$A,0)),0) -> 39 | Y13: =IFERROR(INDEX(PODACI_PRODAJA!H:H,MATCH($A13,PODACI_PRODAJA!$A:$A,0)),0) -> 60 | Z13: =IFERROR(INDEX(PODACI_PRODAJA!I:I,MATCH($A13,PODACI_PRODAJA!$A:$A,0)),0) -> 53 | AA13: =IFERROR(INDEX(PODACI_PRODAJA!J:J,MATCH($A13,PODACI_PRODAJA!$A:$A,0)),0) -> 0 | AB13: =IFERROR(INDEX(PODACI_PRODAJA!K:K,MATCH($A13,PODACI_PRODAJA!$A:$A,0)),0) -> 0 | AC13: =IFERROR(INDEX(PODACI_PRODAJA!L:L,MATCH($A13,PODACI_PRODAJA!$A:$A,0)),0) -> 0 | AD13: =IFERROR(INDEX(PODACI_PRODAJA!M:M,MATCH($A13,PODACI_PRODAJA!$A:$A,0)),0) -> 0
A14: =PODACI_ZALIHE!A11 -> 046203 | B14: =PODACI_ZALIHE!B11 -> ZELENA OBLOGA ZA ZID NATURA BOSCO | C14: =PODACI_ZALIHE!C11 -> 6931 | D14: =PODACI_ZALIHE!D11 -> INTCO INTERNATIONAL (HK) CO., LIMITED | E14: =IF(PODACI_ZALIHE!E11="","",PODACI_ZALIHE!E11) -> 405 | F14: =PODACI_ZALIHE!F11 -> 405 | G14: =IF(E14="","",E14-F14) -> 0 | H14: =PODACI_PRODAJA!N440 -> 1.63 | I14: =IF(H14<=0,999,ROUND(F14/H14,1)) -> 248.5 | J14: =SUMIFS(ROBA_U_DOLASKU!$C$6:$C$95,ROBA_U_DOLASKU!$A$6:$A$95,A14,ROBA_U_DOLASKU!$H$6:$H$95,1) -> 0 | K14: =SUMIFS(ROBA_U_DOLASKU!$B$6:$B$95,ROBA_U_DOLASKU!$A$6:$A$95,A14,ROBA_U_DOLASKU!$H$6:$H$95,1) -> 0 | L14: =SUMIFS(ROBA_U_DOLASKU!$C$6:$C$95,ROBA_U_DOLASKU!$A$6:$A$95,A14,ROBA_U_DOLASKU!$H$6:$H$95,2) -> 0 | M14: =SUMIFS(ROBA_U_DOLASKU!$B$6:$B$95,ROBA_U_DOLASKU!$A$6:$A$95,A14,ROBA_U_DOLASKU!$H$6:$H$95,2) -> 0 | N14: =SUMIFS(ROBA_U_DOLASKU!$C$6:$C$95,ROBA_U_DOLASKU!$A$6:$A$95,A14,ROBA_U_DOLASKU!$H$6:$H$95,3) -> 0 | O14: =SUMIFS(ROBA_U_DOLASKU!$B$6:$B$95,ROBA_U_DOLASKU!$A$6:$A$95,A14,ROBA_U_DOLASKU!$H$6:$H$95,3) -> 0 | P14: =IF(H14<=0,999,IF(O14>0,ROUND((F14-H14*N14+K14+M14+O14)/H14,1),IF(M14>0,ROUND((F14-H14*L14+K14+M14)/H14,1),IF(K14>0,ROUND((F14-H14*J14+K14)/H14,1),I14)))) -> 248.5 | Q14: =IF(H14<=0,"Nema prodaje",IF(AND(K14=0,M14=0,O14=0),IF(I14<POSTAVKE!$B$6,"Naruči odmah","Sve u redu"),IF(F14-H14*J14<0,"Rupa za ~"&TEXT(I14,"0.0")&" mj.",IF(AND(M14>0,F14-H14*L14+K14<0),"Rupa nakon 1. dolaska",IF(AND(O14>0,F14-H14*N14+K14+M14<0),"Rupa nakon 2. dolaska",IF(P14<POSTAVKE!$B$6,"Količina nije dovoljna",IF(I14>=POSTAVKE!$B$6,"Sve u redu","Stiže na vrijeme"))))))) -> Sve u redu | S14: =IFERROR(INDEX(PODACI_PRODAJA!B:B,MATCH($A14,PODACI_PRODAJA!$A:$A,0)),0) -> 0 | T14: =IFERROR(INDEX(PODACI_PRODAJA!C:C,MATCH($A14,PODACI_PRODAJA!$A:$A,0)),0) -> 0 | U14: =IFERROR(INDEX(PODACI_PRODAJA!D:D,MATCH($A14,PODACI_PRODAJA!$A:$A,0)),0) -> 0 | V14: =IFERROR(INDEX(PODACI_PRODAJA!E:E,MATCH($A14,PODACI_PRODAJA!$A:$A,0)),0) -> 0 | W14: =IFERROR(INDEX(PODACI_PRODAJA!F:F,MATCH($A14,PODACI_PRODAJA!$A:$A,0)),0) -> 0 | X14: =IFERROR(INDEX(PODACI_PRODAJA!G:G,MATCH($A14,PODACI_PRODAJA!$A:$A,0)),0) -> 0 | Y14: =IFERROR(INDEX(PODACI_PRODAJA!H:H,MATCH($A14,PODACI_PRODAJA!$A:$A,0)),0) -> 13 | Z14: =IFERROR(INDEX(PODACI_PRODAJA!I:I,MATCH($A14,PODACI_PRODAJA!$A:$A,0)),0) -> 0 | AA14: =IFERROR(INDEX(PODACI_PRODAJA!J:J,MATCH($A14,PODACI_PRODAJA!$A:$A,0)),0) -> 0 | AB14: =IFERROR(INDEX(PODACI_PRODAJA!K:K,MATCH($A14,PODACI_PRODAJA!$A:$A,0)),0) -> 0 | AC14: =IFERROR(INDEX(PODACI_PRODAJA!L:L,MATCH($A14,PODACI_PRODAJA!$A:$A,0)),0) -> 0 | AD14: =IFERROR(INDEX(PODACI_PRODAJA!M:M,MATCH($A14,PODACI_PRODAJA!$A:$A,0)),0) -> 0
A15: =PODACI_ZALIHE!A12 -> 046205 | B15: =PODACI_ZALIHE!B12 -> ZELENA OBLOGA ZA ZID NATURA TERRANA | C15: =PODACI_ZALIHE!C12 -> 6931 | D15: =PODACI_ZALIHE!D12 -> INTCO INTERNATIONAL (HK) CO., LIMITED | E15: =IF(PODACI_ZALIHE!E12="","",PODACI_ZALIHE!E12) -> 405 | F15: =PODACI_ZALIHE!F12 -> 405 | G15: =IF(E15="","",E15-F15) -> 0 | H15: =PODACI_PRODAJA!N442 -> 1.63 | I15: =IF(H15<=0,999,ROUND(F15/H15,1)) -> 248.5 | J15: =SUMIFS(ROBA_U_DOLASKU!$C$6:$C$95,ROBA_U_DOLASKU!$A$6:$A$95,A15,ROBA_U_DOLASKU!$H$6:$H$95,1) -> 0 | K15: =SUMIFS(ROBA_U_DOLASKU!$B$6:$B$95,ROBA_U_DOLASKU!$A$6:$A$95,A15,ROBA_U_DOLASKU!$H$6:$H$95,1) -> 0 | L15: =SUMIFS(ROBA_U_DOLASKU!$C$6:$C$95,ROBA_U_DOLASKU!$A$6:$A$95,A15,ROBA_U_DOLASKU!$H$6:$H$95,2) -> 0 | M15: =SUMIFS(ROBA_U_DOLASKU!$B$6:$B$95,ROBA_U_DOLASKU!$A$6:$A$95,A15,ROBA_U_DOLASKU!$H$6:$H$95,2) -> 0 | N15: =SUMIFS(ROBA_U_DOLASKU!$C$6:$C$95,ROBA_U_DOLASKU!$A$6:$A$95,A15,ROBA_U_DOLASKU!$H$6:$H$95,3) -> 0 | O15: =SUMIFS(ROBA_U_DOLASKU!$B$6:$B$95,ROBA_U_DOLASKU!$A$6:$A$95,A15,ROBA_U_DOLASKU!$H$6:$H$95,3) -> 0 | P15: =IF(H15<=0,999,IF(O15>0,ROUND((F15-H15*N15+K15+M15+O15)/H15,1),IF(M15>0,ROUND((F15-H15*L15+K15+M15)/H15,1),IF(K15>0,ROUND((F15-H15*J15+K15)/H15,1),I15)))) -> 248.5 | Q15: =IF(H15<=0,"Nema prodaje",IF(AND(K15=0,M15=0,O15=0),IF(I15<POSTAVKE!$B$6,"Naruči odmah","Sve u redu"),IF(F15-H15*J15<0,"Rupa za ~"&TEXT(I15,"0.0")&" mj.",IF(AND(M15>0,F15-H15*L15+K15<0),"Rupa nakon 1. dolaska",IF(AND(O15>0,F15-H15*N15+K15+M15<0),"Rupa nakon 2. dolaska",IF(P15<POSTAVKE!$B$6,"Količina nije dovoljna",IF(I15>=POSTAVKE!$B$6,"Sve u redu","Stiže na vrijeme"))))))) -> Sve u redu | S15: =IFERROR(INDEX(PODACI_PRODAJA!B:B,MATCH($A15,PODACI_PRODAJA!$A:$A,0)),0) -> 0 | T15: =IFERROR(INDEX(PODACI_PRODAJA!C:C,MATCH($A15,PODACI_PRODAJA!$A:$A,0)),0) -> 0 | U15: =IFERROR(INDEX(PODACI_PRODAJA!D:D,MATCH($A15,PODACI_PRODAJA!$A:$A,0)),0) -> 0 | V15: =IFERROR(INDEX(PODACI_PRODAJA!E:E,MATCH($A15,PODACI_PRODAJA!$A:$A,0)),0) -> 0 | W15: =IFERROR(INDEX(PODACI_PRODAJA!F:F,MATCH($A15,PODACI_PRODAJA!$A:$A,0)),0) -> 0 | X15: =IFERROR(INDEX(PODACI_PRODAJA!G:G,MATCH($A15,PODACI_PRODAJA!$A:$A,0)),0) -> 0 | Y15: =IFERROR(INDEX(PODACI_PRODAJA!H:H,MATCH($A15,PODACI_PRODAJA!$A:$A,0)),0) -> 13 | Z15: =IFERROR(INDEX(PODACI_PRODAJA!I:I,MATCH($A15,PODACI_PRODAJA!$A:$A,0)),0) -> 0 | AA15: =IFERROR(INDEX(PODACI_PRODAJA!J:J,MATCH($A15,PODACI_PRODAJA!$A:$A,0)),0) -> 0 | AB15: =IFERROR(INDEX(PODACI_PRODAJA!K:K,MATCH($A15,PODACI_PRODAJA!$A:$A,0)),0) -> 0 | AC15: =IFERROR(INDEX(PODACI_PRODAJA!L:L,MATCH($A15,PODACI_PRODAJA!$A:$A,0)),0) -> 0 | AD15: =IFERROR(INDEX(PODACI_PRODAJA!M:M,MATCH($A15,PODACI_PRODAJA!$A:$A,0)),0) -> 0
A16: =PODACI_ZALIHE!A13 -> 17173 | B16: =PODACI_ZALIHE!B13 -> NERO KUPAONSKA KUKICA ZA RUČNIK - CRNA | C16: =PODACI_ZALIHE!C13 -> 6458 | D16: =PODACI_ZALIHE!D13 -> BOJIA TRADING LIMITED | E16: =IF(PODACI_ZALIHE!E13="","",PODACI_ZALIHE!E13) -> 401 | F16: =PODACI_ZALIHE!F13 -> 401 | G16: =IF(E16="","",E16-F16) -> 0 | H16: =PODACI_PRODAJA!N591 -> 4 | I16: =IF(H16<=0,999,ROUND(F16/H16,1)) -> 100.3 | J16: =SUMIFS(ROBA_U_DOLASKU!$C$6:$C$95,ROBA_U_DOLASKU!$A$6:$A$95,A16,ROBA_U_DOLASKU!$H$6:$H$95,1) -> 0 | K16: =SUMIFS(ROBA_U_DOLASKU!$B$6:$B$95,ROBA_U_DOLASKU!$A$6:$A$95,A16,ROBA_U_DOLASKU!$H$6:$H$95,1) -> 0 | L16: =SUMIFS(ROBA_U_DOLASKU!$C$6:$C$95,ROBA_U_DOLASKU!$A$6:$A$95,A16,ROBA_U_DOLASKU!$H$6:$H$95,2) -> 0 | M16: =SUMIFS(ROBA_U_DOLASKU!$B$6:$B$95,ROBA_U_DOLASKU!$A$6:$A$95,A16,ROBA_U_DOLASKU!$H$6:$H$95,2) -> 0 | N16: =SUMIFS(ROBA_U_DOLASKU!$C$6:$C$95,ROBA_U_DOLASKU!$A$6:$A$95,A16,ROBA_U_DOLASKU!$H$6:$H$95,3) -> 0 | O16: =SUMIFS(ROBA_U_DOLASKU!$B$6:$B$95,ROBA_U_DOLASKU!$A$6:$A$95,A16,ROBA_U_DOLASKU!$H$6:$H$95,3) -> 0 | P16: =IF(H16<=0,999,IF(O16>0,ROUND((F16-H16*N16+K16+M16+O16)/H16,1),IF(M16>0,ROUND((F16-H16*L16+K16+M16)/H16,1),IF(K16>0,ROUND((F16-H16*J16+K16)/H16,1),I16)))) -> 100.3 | Q16: =IF(H16<=0,"Nema prodaje",IF(AND(K16=0,M16=0,O16=0),IF(I16<POSTAVKE!$B$6,"Naruči odmah","Sve u redu"),IF(F16-H16*J16<0,"Rupa za ~"&TEXT(I16,"0.0")&" mj.",IF(AND(M16>0,F16-H16*L16+K16<0),"Rupa nakon 1. dolaska",IF(AND(O16>0,F16-H16*N16+K16+M16<0),"Rupa nakon 2. dolaska",IF(P16<POSTAVKE!$B$6,"Količina nije dovoljna",IF(I16>=POSTAVKE!$B$6,"Sve u redu","Stiže na vrijeme"))))))) -> Sve u redu | S16: =IFERROR(INDEX(PODACI_PRODAJA!B:B,MATCH($A16,PODACI_PRODAJA!$A:$A,0)),0) -> 0 | T16: =IFERROR(INDEX(PODACI_PRODAJA!C:C,MATCH($A16,PODACI_PRODAJA!$A:$A,0)),0) -> 1 | U16: =IFERROR(INDEX(PODACI_PRODAJA!D:D,MATCH($A16,PODACI_PRODAJA!$A:$A,0)),0) -> 0 | V16: =IFERROR(INDEX(PODACI_PRODAJA!E:E,MATCH($A16,PODACI_PRODAJA!$A:$A,0)),0) -> 7 | W16: =IFERROR(INDEX(PODACI_PRODAJA!F:F,MATCH($A16,PODACI_PRODAJA!$A:$A,0)),0) -> 12 | X16: =IFERROR(INDEX(PODACI_PRODAJA!G:G,MATCH($A16,PODACI_PRODAJA!$A:$A,0)),0) -> 2 | Y16: =IFERROR(INDEX(PODACI_PRODAJA!H:H,MATCH($A16,PODACI_PRODAJA!$A:$A,0)),0) -> 10 | Z16: =IFERROR(INDEX(PODACI_PRODAJA!I:I,MATCH($A16,PODACI_PRODAJA!$A:$A,0)),0) -> 0 | AA16: =IFERROR(INDEX(PODACI_PRODAJA!J:J,MATCH($A16,PODACI_PRODAJA!$A:$A,0)),0) -> 0 | AB16: =IFERROR(INDEX(PODACI_PRODAJA!K:K,MATCH($A16,PODACI_PRODAJA!$A:$A,0)),0) -> 0 | AC16: =IFERROR(INDEX(PODACI_PRODAJA!L:L,MATCH($A16,PODACI_PRODAJA!$A:$A,0)),0) -> 0 | AD16: =IFERROR(INDEX(PODACI_PRODAJA!M:M,MATCH($A16,PODACI_PRODAJA!$A:$A,0)),0) -> 0
A17: =PODACI_ZALIHE!A14 -> RDE320230 | B17: =PODACI_ZALIHE!B14 -> DASKA SOFT CLOSE ZA MOHO MONOBLOCK | C17: =PODACI_ZALIHE!C14 -> 6341 | D17: =PODACI_ZALIHE!D14 -> CORRAVENI INDUSTRIES CO., LTD. | E17: =IF(PODACI_ZALIHE!E14="","",PODACI_ZALIHE!E14) -> 380 | F17: =PODACI_ZALIHE!F14 -> 380 | G17: =IF(E17="","",E17-F17) -> 0 | H17: 0 | I17: =IF(H17<=0,999,ROUND(F17/H17,1)) -> 999 | J17: =SUMIFS(ROBA_U_DOLASKU!$C$6:$C$95,ROBA_U_DOLASKU!$A$6:$A$95,A17,ROBA_U_DOLASKU!$H$6:$H$95,1) -> 0 | K17: =SUMIFS(ROBA_U_DOLASKU!$B$6:$B$95,ROBA_U_DOLASKU!$A$6:$A$95,A17,ROBA_U_DOLASKU!$H$6:$H$95,1) -> 0 | L17: =SUMIFS(ROBA_U_DOLASKU!$C$6:$C$95,ROBA_U_DOLASKU!$A$6:$A$95,A17,ROBA_U_DOLASKU!$H$6:$H$95,2) -> 0 | M17: =SUMIFS(ROBA_U_DOLASKU!$B$6:$B$95,ROBA_U_DOLASKU!$A$6:$A$95,A17,ROBA_U_DOLASKU!$H$6:$H$95,2) -> 0 | N17: =SUMIFS(ROBA_U_DOLASKU!$C$6:$C$95,ROBA_U_DOLASKU!$A$6:$A$95,A17,ROBA_U_DOLASKU!$H$6:$H$95,3) -> 0 | O17: =SUMIFS(ROBA_U_DOLASKU!$B$6:$B$95,ROBA_U_DOLASKU!$A$6:$A$95,A17,ROBA_U_DOLASKU!$H$6:$H$95,3) -> 0 | P17: =IF(H17<=0,999,IF(O17>0,ROUND((F17-H17*N17+K17+M17+O17)/H17,1),IF(M17>0,ROUND((F17-H17*L17+K17+M17)/H17,1),IF(K17>0,ROUND((F17-H17*J17+K17)/H17,1),I17)))) -> 999 | Q17: =IF(H17<=0,"Nema prodaje",IF(AND(K17=0,M17=0,O17=0),IF(I17<POSTAVKE!$B$6,"Naruči odmah","Sve u redu"),IF(F17-H17*J17<0,"Rupa za ~"&TEXT(I17,"0.0")&" mj.",IF(AND(M17>0,F17-H17*L17+K17<0),"Rupa nakon 1. dolaska",IF(AND(O17>0,F17-H17*N17+K17+M17<0),"Rupa nakon 2. dolaska",IF(P17<POSTAVKE!$B$6,"Količina nije dovoljna",IF(I17>=POSTAVKE!$B$6,"Sve u redu","Stiže na vrijeme"))))))) -> Nema prodaje | S17: =IFERROR(INDEX(PODACI_PRODAJA!B:B,MATCH($A17,PODACI_PRODAJA!$A:$A,0)),0) -> 0 | T17: =IFERROR(INDEX(PODACI_PRODAJA!C:C,MATCH($A17,PODACI_PRODAJA!$A:$A,0)),0) -> 0 | U17: =IFERROR(INDEX(PODACI_PRODAJA!D:D,MATCH($A17,PODACI_PRODAJA!$A:$A,0)),0) -> 0 | V17: =IFERROR(INDEX(PODACI_PRODAJA!E:E,MATCH($A17,PODACI_PRODAJA!$A:$A,0)),0) -> 0 | W17: =IFERROR(INDEX(PODACI_PRODAJA!F:F,MATCH($A17,PODACI_PRODAJA!$A:$A,0)),0) -> 0 | X17: =IFERROR(INDEX(PODACI_PRODAJA!G:G,MATCH($A17,PODACI_PRODAJA!$A:$A,0)),0) -> 0 | Y17: =IFERROR(INDEX(PODACI_PRODAJA!H:H,MATCH($A17,PODACI_PRODAJA!$A:$A,0)),0) -> 0 | Z17: =IFERROR(INDEX(PODACI_PRODAJA!I:I,MATCH($A17,PODACI_PRODAJA!$A:$A,0)),0) -> 0 | AA17: =IFERROR(INDEX(PODACI_PRODAJA!J:J,MATCH($A17,PODACI_PRODAJA!$A:$A,0)),0) -> 0 | AB17: =IFERROR(INDEX(PODACI_PRODAJA!K:K,MATCH($A17,PODACI_PRODAJA!$A:$A,0)),0) -> 0 | AC17: =IFERROR(INDEX(PODACI_PRODAJA!L:L,MATCH($A17,PODACI_PRODAJA!$A:$A,0)),0) -> 0 | AD17: =IFERROR(INDEX(PODACI_PRODAJA!M:M,MATCH($A17,PODACI_PRODAJA!$A:$A,0)),0) -> 0
A18: =PODACI_ZALIHE!A15 -> 00720 | B18: =PODACI_ZALIHE!B15 -> KOTAČIĆI ZA TUŠ KABINE 4/1 | C18: =PODACI_ZALIHE!C15 -> 4328 | D18: =PODACI_ZALIHE!D15 -> HANGZHOU DUHUI IMPORT AND EXPORT CO.,LTD | E18: =IF(PODACI_ZALIHE!E15="","",PODACI_ZALIHE!E15) -> 385 | F18: =PODACI_ZALIHE!F15 -> 354 | G18: =IF(E18="","",E18-F18) -> 31 | H18: =PODACI_PRODAJA!N12 -> 83.13 | I18: =IF(H18<=0,999,ROUND(F18/H18,1)) -> 4.3 | J18: =SUMIFS(ROBA_U_DOLASKU!$C$6:$C$95,ROBA_U_DOLASKU!$A$6:$A$95,A18,ROBA_U_DOLASKU!$H$6:$H$95,1) -> 0 | K18: =SUMIFS(ROBA_U_DOLASKU!$B$6:$B$95,ROBA_U_DOLASKU!$A$6:$A$95,A18,ROBA_U_DOLASKU!$H$6:$H$95,1) -> 0 | L18: =SUMIFS(ROBA_U_DOLASKU!$C$6:$C$95,ROBA_U_DOLASKU!$A$6:$A$95,A18,ROBA_U_DOLASKU!$H$6:$H$95,2) -> 0 | M18: =SUMIFS(ROBA_U_DOLASKU!$B$6:$B$95,ROBA_U_DOLASKU!$A$6:$A$95,A18,ROBA_U_DOLASKU!$H$6:$H$95,2) -> 0 | N18: =SUMIFS(ROBA_U_DOLASKU!$C$6:$C$95,ROBA_U_DOLASKU!$A$6:$A$95,A18,ROBA_U_DOLASKU!$H$6:$H$95,3) -> 0 | O18: =SUMIFS(ROBA_U_DOLASKU!$B$6:$B$95,ROBA_U_DOLASKU!$A$6:$A$95,A18,ROBA_U_DOLASKU!$H$6:$H$95,3) -> 0 | P18: =IF(H18<=0,999,IF(O18>0,ROUND((F18-H18*N18+K18+M18+O18)/H18,1),IF(M18>0,ROUND((F18-H18*L18+K18+M18)/H18,1),IF(K18>0,ROUND((F18-H18*J18+K18)/H18,1),I18)))) -> 4.3 | Q18: =IF(H18<=0,"Nema prodaje",IF(AND(K18=0,M18=0,O18=0),IF(I18<POSTAVKE!$B$6,"Naruči odmah","Sve u redu"),IF(F18-H18*J18<0,"Rupa za ~"&TEXT(I18,"0.0")&" mj.",IF(AND(M18>0,F18-H18*L18+K18<0),"Rupa nakon 1. dolaska",IF(AND(O18>0,F18-H18*N18+K18+M18<0),"Rupa nakon 2. dolaska",IF(P18<POSTAVKE!$B$6,"Količina nije dovoljna",IF(I18>=POSTAVKE!$B$6,"Sve u redu","Stiže na vrijeme"))))))) -> Naruči odmah | S18: =IFERROR(INDEX(PODACI_PRODAJA!B:B,MATCH($A18,PODACI_PRODAJA!$A:$A,0)),0) -> 66 | T18: =IFERROR(INDEX(PODACI_PRODAJA!C:C,MATCH($A18,PODACI_PRODAJA!$A:$A,0)),0) -> 43 | U18: =IFERROR(INDEX(PODACI_PRODAJA!D:D,MATCH($A18,PODACI_PRODAJA!$A:$A,0)),0) -> 65 | V18: =IFERROR(INDEX(PODACI_PRODAJA!E:E,MATCH($A18,PODACI_PRODAJA!$A:$A,0)),0) -> 80 | W18: =IFERROR(INDEX(PODACI_PRODAJA!F:F,MATCH($A18,PODACI_PRODAJA!$A:$A,0)),0) -> 66 | X18: =IFERROR(INDEX(PODACI_PRODAJA!G:G,MATCH($A18,PODACI_PRODAJA!$A:$A,0)),0) -> 98 | Y18: =IFERROR(INDEX(PODACI_PRODAJA!H:H,MATCH($A18,PODACI_PRODAJA!$A:$A,0)),0) -> 141 | Z18: =IFERROR(INDEX(PODACI_PRODAJA!I:I,MATCH($A18,PODACI_PRODAJA!$A:$A,0)),0) -> 106 | AA18: =IFERROR(INDEX(PODACI_PRODAJA!J:J,MATCH($A18,PODACI_PRODAJA!$A:$A,0)),0) -> 31 | AB18: =IFERROR(INDEX(PODACI_PRODAJA!K:K,MATCH($A18,PODACI_PRODAJA!$A:$A,0)),0) -> 0 | AC18: =IFERROR(INDEX(PODACI_PRODAJA!L:L,MATCH($A18,PODACI_PRODAJA!$A:$A,0)),0) -> 0 | AD18: =IFERROR(INDEX(PODACI_PRODAJA!M:M,MATCH($A18,PODACI_PRODAJA!$A:$A,0)),0) -> 0
A19: =PODACI_ZALIHE!A16 -> 046204 | B19: =PODACI_ZALIHE!B16 -> ZELENA OBLOGA ZA ZID NATURA HERBA | C19: =PODACI_ZALIHE!C16 -> 6931 | D19: =PODACI_ZALIHE!D16 -> INTCO INTERNATIONAL (HK) CO., LIMITED | E19: =IF(PODACI_ZALIHE!E16="","",PODACI_ZALIHE!E16) -> 345 | F19: =PODACI_ZALIHE!F16 -> 345 | G19: =IF(E19="","",E19-F19) -> 0 | H19: =PODACI_PRODAJA!N441 -> 1.63 | I19: =IF(H19<=0,999,ROUND(F19/H19,1)) -> 211.7 | J19: =SUMIFS(ROBA_U_DOLASKU!$C$6:$C$95,ROBA_U_DOLASKU!$A$6:$A$95,A19,ROBA_U_DOLASKU!$H$6:$H$95,1) -> 0 | K19: =SUMIFS(ROBA_U_DOLASKU!$B$6:$B$95,ROBA_U_DOLASKU!$A$6:$A$95,A19,ROBA_U_DOLASKU!$H$6:$H$95,1) -> 0 | L19: =SUMIFS(ROBA_U_DOLASKU!$C$6:$C$95,ROBA_U_DOLASKU!$A$6:$A$95,A19,ROBA_U_DOLASKU!$H$6:$H$95,2) -> 0 | M19: =SUMIFS(ROBA_U_DOLASKU!$B$6:$B$95,ROBA_U_DOLASKU!$A$6:$A$95,A19,ROBA_U_DOLASKU!$H$6:$H$95,2) -> 0 | N19: =SUMIFS(ROBA_U_DOLASKU!$C$6:$C$95,ROBA_U_DOLASKU!$A$6:$A$95,A19,ROBA_U_DOLASKU!$H$6:$H$95,3) -> 0 | O19: =SUMIFS(ROBA_U_DOLASKU!$B$6:$B$95,ROBA_U_DOLASKU!$A$6:$A$95,A19,ROBA_U_DOLASKU!$H$6:$H$95,3) -> 0 | P19: =IF(H19<=0,999,IF(O19>0,ROUND((F19-H19*N19+K19+M19+O19)/H19,1),IF(M19>0,ROUND((F19-H19*L19+K19+M19)/H19,1),IF(K19>0,ROUND((F19-H19*J19+K19)/H19,1),I19)))) -> 211.7 | Q19: =IF(H19<=0,"Nema prodaje",IF(AND(K19=0,M19=0,O19=0),IF(I19<POSTAVKE!$B$6,"Naruči odmah","Sve u redu"),IF(F19-H19*J19<0,"Rupa za ~"&TEXT(I19,"0.0")&" mj.",IF(AND(M19>0,F19-H19*L19+K19<0),"Rupa nakon 1. dolaska",IF(AND(O19>0,F19-H19*N19+K19+M19<0),"Rupa nakon 2. dolaska",IF(P19<POSTAVKE!$B$6,"Količina nije dovoljna",IF(I19>=POSTAVKE!$B$6,"Sve u redu","Stiže na vrijeme"))))))) -> Sve u redu | S19: =IFERROR(INDEX(PODACI_PRODAJA!B:B,MATCH($A19,PODACI_PRODAJA!$A:$A,0)),0) -> 0 | T19: =IFERROR(INDEX(PODACI_PRODAJA!C:C,MATCH($A19,PODACI_PRODAJA!$A:$A,0)),0) -> 0 | U19: =IFERROR(INDEX(PODACI_PRODAJA!D:D,MATCH($A19,PODACI_PRODAJA!$A:$A,0)),0) -> 0 | V19: =IFERROR(INDEX(PODACI_PRODAJA!E:E,MATCH($A19,PODACI_PRODAJA!$A:$A,0)),0) -> 0 | W19: =IFERROR(INDEX(PODACI_PRODAJA!F:F,MATCH($A19,PODACI_PRODAJA!$A:$A,0)),0) -> 0 | X19: =IFERROR(INDEX(PODACI_PRODAJA!G:G,MATCH($A19,PODACI_PRODAJA!$A:$A,0)),0) -> 0 | Y19: =IFERROR(INDEX(PODACI_PRODAJA!H:H,MATCH($A19,PODACI_PRODAJA!$A:$A,0)),0) -> 13 | Z19: =IFERROR(INDEX(PODACI_PRODAJA!I:I,MATCH($A19,PODACI_PRODAJA!$A:$A,0)),0) -> 0 | AA19: =IFERROR(INDEX(PODACI_PRODAJA!J:J,MATCH($A19,PODACI_PRODAJA!$A:$A,0)),0) -> 0 | AB19: =IFERROR(INDEX(PODACI_PRODAJA!K:K,MATCH($A19,PODACI_PRODAJA!$A:$A,0)),0) -> 0 | AC19: =IFERROR(INDEX(PODACI_PRODAJA!L:L,MATCH($A19,PODACI_PRODAJA!$A:$A,0)),0) -> 0 | AD19: =IFERROR(INDEX(PODACI_PRODAJA!M:M,MATCH($A19,PODACI_PRODAJA!$A:$A,0)),0) -> 0
A20: =PODACI_ZALIHE!A17 -> 046202 | B20: =PODACI_ZALIHE!B17 -> ZELENA OBLOGA ZA ZID VERDE FOREST | C20: =PODACI_ZALIHE!C17 -> 6931 | D20: =PODACI_ZALIHE!D17 -> INTCO INTERNATIONAL (HK) CO., LIMITED | E20: =IF(PODACI_ZALIHE!E17="","",PODACI_ZALIHE!E17) -> 335 | F20: =PODACI_ZALIHE!F17 -> 335 | G20: =IF(E20="","",E20-F20) -> 0 | H20: =PODACI_PRODAJA!N439 -> 1.63 | I20: =IF(H20<=0,999,ROUND(F20/H20,1)) -> 205.5 | J20: =SUMIFS(ROBA_U_DOLASKU!$C$6:$C$95,ROBA_U_DOLASKU!$A$6:$A$95,A20,ROBA_U_DOLASKU!$H$6:$H$95,1) -> 0 | K20: =SUMIFS(ROBA_U_DOLASKU!$B$6:$B$95,ROBA_U_DOLASKU!$A$6:$A$95,A20,ROBA_U_DOLASKU!$H$6:$H$95,1) -> 0 | L20: =SUMIFS(ROBA_U_DOLASKU!$C$6:$C$95,ROBA_U_DOLASKU!$A$6:$A$95,A20,ROBA_U_DOLASKU!$H$6:$H$95,2) -> 0 | M20: =SUMIFS(ROBA_U_DOLASKU!$B$6:$B$95,ROBA_U_DOLASKU!$A$6:$A$95,A20,ROBA_U_DOLASKU!$H$6:$H$95,2) -> 0 | N20: =SUMIFS(ROBA_U_DOLASKU!$C$6:$C$95,ROBA_U_DOLASKU!$A$6:$A$95,A20,ROBA_U_DOLASKU!$H$6:$H$95,3) -> 0 | O20: =SUMIFS(ROBA_U_DOLASKU!$B$6:$B$95,ROBA_U_DOLASKU!$A$6:$A$95,A20,ROBA_U_DOLASKU!$H$6:$H$95,3) -> 0 | P20: =IF(H20<=0,999,IF(O20>0,ROUND((F20-H20*N20+K20+M20+O20)/H20,1),IF(M20>0,ROUND((F20-H20*L20+K20+M20)/H20,1),IF(K20>0,ROUND((F20-H20*J20+K20)/H20,1),I20)))) -> 205.5 | Q20: =IF(H20<=0,"Nema prodaje",IF(AND(K20=0,M20=0,O20=0),IF(I20<POSTAVKE!$B$6,"Naruči odmah","Sve u redu"),IF(F20-H20*J20<0,"Rupa za ~"&TEXT(I20,"0.0")&" mj.",IF(AND(M20>0,F20-H20*L20+K20<0),"Rupa nakon 1. dolaska",IF(AND(O20>0,F20-H20*N20+K20+M20<0),"Rupa nakon 2. dolaska",IF(P20<POSTAVKE!$B$6,"Količina nije dovoljna",IF(I20>=POSTAVKE!$B$6,"Sve u redu","Stiže na vrijeme"))))))) -> Sve u redu | S20: =IFERROR(INDEX(PODACI_PRODAJA!B:B,MATCH($A20,PODACI_PRODAJA!$A:$A,0)),0) -> 0 | T20: =IFERROR(INDEX(PODACI_PRODAJA!C:C,MATCH($A20,PODACI_PRODAJA!$A:$A,0)),0) -> 0 | U20: =IFERROR(INDEX(PODACI_PRODAJA!D:D,MATCH($A20,PODACI_PRODAJA!$A:$A,0)),0) -> 0 | V20: =IFERROR(INDEX(PODACI_PRODAJA!E:E,MATCH($A20,PODACI_PRODAJA!$A:$A,0)),0) -> 0 | W20: =IFERROR(INDEX(PODACI_PRODAJA!F:F,MATCH($A20,PODACI_PRODAJA!$A:$A,0)),0) -> 0 | X20: =IFERROR(INDEX(PODACI_PRODAJA!G:G,MATCH($A20,PODACI_PRODAJA!$A:$A,0)),0) -> 0 | Y20: =IFERROR(INDEX(PODACI_PRODAJA!H:H,MATCH($A20,PODACI_PRODAJA!$A:$A,0)),0) -> 13 | Z20: =IFERROR(INDEX(PODACI_PRODAJA!I:I,MATCH($A20,PODACI_PRODAJA!$A:$A,0)),0) -> 0 | AA20: =IFERROR(INDEX(PODACI_PRODAJA!J:J,MATCH($A20,PODACI_PRODAJA!$A:$A,0)),0) -> 0 | AB20: =IFERROR(INDEX(PODACI_PRODAJA!K:K,MATCH($A20,PODACI_PRODAJA!$A:$A,0)),0) -> 0 | AC20: =IFERROR(INDEX(PODACI_PRODAJA!L:L,MATCH($A20,PODACI_PRODAJA!$A:$A,0)),0) -> 0 | AD20: =IFERROR(INDEX(PODACI_PRODAJA!M:M,MATCH($A20,PODACI_PRODAJA!$A:$A,0)),0) -> 0
A21: =PODACI_ZALIHE!A18 -> 15399 | B21: =PODACI_ZALIHE!B18 -> PULSE 80 POLUKRUŽNA TUŠ KABINA 80X80X198 | C21: =PODACI_ZALIHE!C18 -> 6163 | D21: =PODACI_ZALIHE!D18 -> HANGZHOU TIANMEI INDUSTRY CO.,LTD | E21: =IF(PODACI_ZALIHE!E18="","",PODACI_ZALIHE!E18) -> 333 | F21: =PODACI_ZALIHE!F18 -> 321 | G21: =IF(E21="","",E21-F21) -> 12 | H21: =PODACI_PRODAJA!N18 -> 52.13 | I21: =IF(H21<=0,999,ROUND(F21/H21,1)) -> 6.2 | J21: =SUMIFS(ROBA_U_DOLASKU!$C$6:$C$95,ROBA_U_DOLASKU!$A$6:$A$95,A21,ROBA_U_DOLASKU!$H$6:$H$95,1) -> 2.4 | K21: =SUMIFS(ROBA_U_DOLASKU!$B$6:$B$95,ROBA_U_DOLASKU!$A$6:$A$95,A21,ROBA_U_DOLASKU!$H$6:$H$95,1) -> 50 | L21: =SUMIFS(ROBA_U_DOLASKU!$C$6:$C$95,ROBA_U_DOLASKU!$A$6:$A$95,A21,ROBA_U_DOLASKU!$H$6:$H$95,2) -> 0 | M21: =SUMIFS(ROBA_U_DOLASKU!$B$6:$B$95,ROBA_U_DOLASKU!$A$6:$A$95,A21,ROBA_U_DOLASKU!$H$6:$H$95,2) -> 0 | N21: =SUMIFS(ROBA_U_DOLASKU!$C$6:$C$95,ROBA_U_DOLASKU!$A$6:$A$95,A21,ROBA_U_DOLASKU!$H$6:$H$95,3) -> 0 | O21: =SUMIFS(ROBA_U_DOLASKU!$B$6:$B$95,ROBA_U_DOLASKU!$A$6:$A$95,A21,ROBA_U_DOLASKU!$H$6:$H$95,3) -> 0 | P21: =IF(H21<=0,999,IF(O21>0,ROUND((F21-H21*N21+K21+M21+O21)/H21,1),IF(M21>0,ROUND((F21-H21*L21+K21+M21)/H21,1),IF(K21>0,ROUND((F21-H21*J21+K21)/H21,1),I21)))) -> 4.7 | Q21: =IF(H21<=0,"Nema prodaje",IF(AND(K21=0,M21=0,O21=0),IF(I21<POSTAVKE!$B$6,"Naruči odmah","Sve u redu"),IF(F21-H21*J21<0,"Rupa za ~"&TEXT(I21,"0.0")&" mj.",IF(AND(M21>0,F21-H21*L21+K21<0),"Rupa nakon 1. dolaska",IF(AND(O21>0,F21-H21*N21+K21+M21<0),"Rupa nakon 2. dolaska",IF(P21<POSTAVKE!$B$6,"Količina nije dovoljna",IF(I21>=POSTAVKE!$B$6,"Sve u redu","Stiže na vrijeme"))))))) -> Količina nije dovoljna | S21: =IFERROR(INDEX(PODACI_PRODAJA!B:B,MATCH($A21,PODACI_PRODAJA!$A:$A,0)),0) -> 45 | T21: =IFERROR(INDEX(PODACI_PRODAJA!C:C,MATCH($A21,PODACI_PRODAJA!$A:$A,0)),0) -> 68 | U21: =IFERROR(INDEX(PODACI_PRODAJA!D:D,MATCH($A21,PODACI_PRODAJA!$A:$A,0)),0) -> 38 | V21: =IFERROR(INDEX(PODACI_PRODAJA!E:E,MATCH($A21,PODACI_PRODAJA!$A:$A,0)),0) -> 83 | W21: =IFERROR(INDEX(PODACI_PRODAJA!F:F,MATCH($A21,PODACI_PRODAJA!$A:$A,0)),0) -> 37 | X21: =IFERROR(INDEX(PODACI_PRODAJA!G:G,MATCH($A21,PODACI_PRODAJA!$A:$A,0)),0) -> 49 | Y21: =IFERROR(INDEX(PODACI_PRODAJA!H:H,MATCH($A21,PODACI_PRODAJA!$A:$A,0)),0) -> 40 | Z21: =IFERROR(INDEX(PODACI_PRODAJA!I:I,MATCH($A21,PODACI_PRODAJA!$A:$A,0)),0) -> 57 | AA21: =IFERROR(INDEX(PODACI_PRODAJA!J:J,MATCH($A21,PODACI_PRODAJA!$A:$A,0)),0) -> 12 | AB21: =IFERROR(INDEX(PODACI_PRODAJA!K:K,MATCH($A21,PODACI_PRODAJA!$A:$A,0)),0) -> 0 | AC21: =IFERROR(INDEX(PODACI_PRODAJA!L:L,MATCH($A21,PODACI_PRODAJA!$A:$A,0)),0) -> 0 | AD21: =IFERROR(INDEX(PODACI_PRODAJA!M:M,MATCH($A21,PODACI_PRODAJA!$A:$A,0)),0) -> 0
